Process A [NEW] (arrival time 9 ms) 16 CPU bursts
Process B [NEW] (arrival time 18 ms) 21 CPU bursts
Process C [NEW] (arrival time 42 ms) 4 CPU bursts
Process D [NEW] (arrival time 156 ms) 11 CPU bursts
Process E [NEW] (arrival time 134 ms) 55 CPU bursts
Process F [NEW] (arrival time 106 ms) 34 CPU bursts
Process G [NEW] (arrival time 65 ms) 80 CPU bursts
Process H [NEW] (arrival time 11 ms) 83 CPU bursts
Process I [NEW] (arrival time 68 ms) 77 CPU bursts
Process J [NEW] (arrival time 0 ms) 10 CPU bursts
Process K [NEW] (arrival time 7 ms) 13 CPU bursts
Process L [NEW] (arrival time 189 ms) 7 CPU bursts
Process M [NEW] (arrival time 16 ms) 48 CPU bursts
Process N [NEW] (arrival time 122 ms) 31 CPU bursts
Process O [NEW] (arrival time 29 ms) 31 CPU bursts
Process P [NEW] (arrival time 159 ms) 16 CPU bursts
time 0ms: Simulator started for FCFS [Q <empty>]
time 0ms: Process J arrived; added to ready queue [Q J]
time 2ms: Process J started using the CPU for 40ms burst [Q <empty>]
time 7ms: Process K arrived; added to ready queue [Q K]
time 9ms: Process A arrived; added to ready queue [Q K A]
time 11ms: Process H arrived; added to ready queue [Q K A H]
time 16ms: Process M arrived; added to ready queue [Q K A H M]
time 18ms: Process B arrived; added to ready queue [Q K A H M B]
time 29ms: Process O arrived; added to ready queue [Q K A H M B O]
time 42ms: Process J completed a CPU burst; 9 bursts to go [Q K A H M B O]
time 42ms: Process J switching out of CPU; will block on I/O until time 47ms [Q K A H M B O]
time 42ms: Process C arrived; added to ready queue [Q K A H M B O C]
time 46ms: Process K started using the CPU for 64ms burst [Q A H M B O C]
time 47ms: Process J completed I/O; added to ready queue [Q A H M B O C J]
time 65ms: Process G arrived; added to ready queue [Q A H M B O C J G]
time 68ms: Process I arrived; added to ready queue [Q A H M B O C J G I]
time 106ms: Process F arrived; added to ready queue [Q A H M B O C J G I F]
time 110ms: Process K completed a CPU burst; 12 bursts to go [Q A H M B O C J G I F]
time 110ms: Process K switching out of CPU; will block on I/O until time 208ms [Q A H M B O C J G I F]
time 114ms: Process A started using the CPU for 56ms burst [Q H M B O C J G I F]
time 122ms: Process N arrived; added to ready queue [Q H M B O C J G I F N]
time 134ms: Process E arrived; added to ready queue [Q H M B O C J G I F N E]
time 156ms: Process D arrived; added to ready queue [Q H M B O C J G I F N E D]
time 159ms: Process P arrived; added to ready queue [Q H M B O C J G I F N E D P]
time 170ms: Process A completed a CPU burst; 15 bursts to go [Q H M B O C J G I F N E D P]
time 170ms: Process A switching out of CPU; will block on I/O until time 195ms [Q H M B O C J G I F N E D P]
time 174ms: Process H started using the CPU for 96ms burst [Q M B O C J G I F N E D P]
time 189ms: Process L arrived; added to ready queue [Q M B O C J G I F N E D P L]
time 195ms: Process A completed I/O; added to ready queue [Q M B O C J G I F N E D P L A]
time 208ms: Process K completed I/O; added to ready queue [Q M B O C J G I F N E D P L A K]
time 270ms: Process H completed a CPU burst; 82 bursts to go [Q M B O C J G I F N E D P L A K]
time 270ms: Process H switching out of CPU; will block on I/O until time 339ms [Q M B O C J G I F N E D P L A K]
time 274ms: Process M started using the CPU for 22ms burst [Q B O C J G I F N E D P L A K]
time 296ms: Process M completed a CPU burst; 47 bursts to go [Q B O C J G I F N E D P L A K]
time 296ms: Process M switching out of CPU; will block on I/O until time 315ms [Q B O C J G I F N E D P L A K]
time 300ms: Process B started using the CPU for 106ms burst [Q O C J G I F N E D P L A K]
time 315ms: Process M completed I/O; added to ready queue [Q O C J G I F N E D P L A K M]
time 339ms: Process H completed I/O; added to ready queue [Q O C J G I F N E D P L A K M H]
time 406ms: Process B completed a CPU burst; 20 bursts to go [Q O C J G I F N E D P L A K M H]
time 406ms: Process B switching out of CPU; will block on I/O until time 564ms [Q O C J G I F N E D P L A K M H]
time 410ms: Process O started using the CPU for 156ms burst [Q C J G I F N E D P L A K M H]
time 564ms: Process B completed I/O; added to ready queue [Q C J G I F N E D P L A K M H B]
time 566ms: Process O completed a CPU burst; 30 bursts to go [Q C J G I F N E D P L A K M H B]
time 566ms: Process O switching out of CPU; will block on I/O until time 635ms [Q C J G I F N E D P L A K M H B]
time 570ms: Process C started using the CPU for 94ms burst [Q J G I F N E D P L A K M H B]
time 635ms: Process O completed I/O; added to ready queue [Q J G I F N E D P L A K M H B O]
time 664ms: Process C completed a CPU burst; 3 bursts to go [Q J G I F N E D P L A K M H B O]
time 664ms: Process C switching out of CPU; will block on I/O until time 824ms [Q J G I F N E D P L A K M H B O]
time 668ms: Process J started using the CPU for 204ms burst [Q G I F N E D P L A K M H B O]
time 824ms: Process C completed I/O; added to ready queue [Q G I F N E D P L A K M H B O C]
time 872ms: Process J completed a CPU burst; 8 bursts to go [Q G I F N E D P L A K M H B O C]
time 872ms: Process J switching out of CPU; will block on I/O until time 944ms [Q G I F N E D P L A K M H B O C]
time 876ms: Process G started using the CPU for 70ms burst [Q I F N E D P L A K M H B O C]
time 944ms: Process J completed I/O; added to ready queue [Q I F N E D P L A K M H B O C J]
time 946ms: Process G completed a CPU burst; 79 bursts to go [Q I F N E D P L A K M H B O C J]
time 946ms: Process G switching out of CPU; will block on I/O until time 979ms [Q I F N E D P L A K M H B O C J]
time 950ms: Process I started using the CPU for 220ms burst [Q F N E D P L A K M H B O C J]
time 979ms: Process G completed I/O; added to ready queue [Q F N E D P L A K M H B O C J G]
time 1170ms: Process I completed a CPU burst; 76 bursts to go [Q F N E D P L A K M H B O C J G]
time 1170ms: Process I switching out of CPU; will block on I/O until time 1191ms [Q F N E D P L A K M H B O C J G]
time 1174ms: Process F started using the CPU for 129ms burst [Q N E D P L A K M H B O C J G]
time 1191ms: Process I completed I/O; added to ready queue [Q N E D P L A K M H B O C J G I]
time 1303ms: Process F completed a CPU burst; 33 bursts to go [Q N E D P L A K M H B O C J G I]
time 1303ms: Process F switching out of CPU; will block on I/O until time 1362ms [Q N E D P L A K M H B O C J G I]
time 1307ms: Process N started using the CPU for 213ms burst [Q E D P L A K M H B O C J G I]
time 1362ms: Process F completed I/O; added to ready queue [Q E D P L A K M H B O C J G I F]
time 1520ms: Process N completed a CPU burst; 30 bursts to go [Q E D P L A K M H B O C J G I F]
time 1520ms: Process N switching out of CPU; will block on I/O until time 1537ms [Q E D P L A K M H B O C J G I F]
time 1524ms: Process E started using the CPU for 152ms burst [Q D P L A K M H B O C J G I F]
time 1537ms: Process N completed I/O; added to ready queue [Q D P L A K M H B O C J G I F N]
time 1676ms: Process E completed a CPU burst; 54 bursts to go [Q D P L A K M H B O C J G I F N]
time 1676ms: Process E switching out of CPU; will block on I/O until time 1724ms [Q D P L A K M H B O C J G I F N]
time 1680ms: Process D started using the CPU for 148ms burst [Q P L A K M H B O C J G I F N]
time 1724ms: Process E completed I/O; added to ready queue [Q P L A K M H B O C J G I F N E]
time 1828ms: Process D completed a CPU burst; 10 bursts to go [Q P L A K M H B O C J G I F N E]
time 1828ms: Process D switching out of CPU; will block on I/O until time 1832ms [Q P L A K M H B O C J G I F N E]
time 1832ms: Process P started using the CPU for 4ms burst [Q L A K M H B O C J G I F N E]
time 1832ms: Process D completed I/O; added to ready queue [Q L A K M H B O C J G I F N E D]
time 1836ms: Process P completed a CPU burst; 15 bursts to go [Q L A K M H B O C J G I F N E D]
time 1836ms: Process P switching out of CPU; will block on I/O until time 2023ms [Q L A K M H B O C J G I F N E D]
time 1840ms: Process L started using the CPU for 135ms burst [Q A K M H B O C J G I F N E D]
time 1975ms: Process L completed a CPU burst; 6 bursts to go [Q A K M H B O C J G I F N E D]
time 1975ms: Process L switching out of CPU; will block on I/O until time 2051ms [Q A K M H B O C J G I F N E D]
time 1979ms: Process A started using the CPU for 60ms burst [Q K M H B O C J G I F N E D]
time 2023ms: Process P completed I/O; added to ready queue [Q K M H B O C J G I F N E D P]
time 2039ms: Process A completed a CPU burst; 14 bursts to go [Q K M H B O C J G I F N E D P]
time 2039ms: Process A switching out of CPU; will block on I/O until time 2194ms [Q K M H B O C J G I F N E D P]
time 2043ms: Process K started using the CPU for 56ms burst [Q M H B O C J G I F N E D P]
time 2051ms: Process L completed I/O; added to ready queue [Q M H B O C J G I F N E D P L]
time 2099ms: Process K completed a CPU burst; 11 bursts to go [Q M H B O C J G I F N E D P L]
time 2099ms: Process K switching out of CPU; will block on I/O until time 2174ms [Q M H B O C J G I F N E D P L]
time 2103ms: Process M started using the CPU for 93ms burst [Q H B O C J G I F N E D P L]
time 2174ms: Process K completed I/O; added to ready queue [Q H B O C J G I F N E D P L K]
time 2194ms: Process A completed I/O; added to ready queue [Q H B O C J G I F N E D P L K A]
time 2196ms: Process M completed a CPU burst; 46 bursts to go [Q H B O C J G I F N E D P L K A]
time 2196ms: Process M switching out of CPU; will block on I/O until time 2240ms [Q H B O C J G I F N E D P L K A]
time 2200ms: Process H started using the CPU for 48ms burst [Q B O C J G I F N E D P L K A]
time 2240ms: Process M completed I/O; added to ready queue [Q B O C J G I F N E D P L K A M]
time 2248ms: Process H completed a CPU burst; 81 bursts to go [Q B O C J G I F N E D P L K A M]
time 2248ms: Process H switching out of CPU; will block on I/O until time 2272ms [Q B O C J G I F N E D P L K A M]
time 2252ms: Process B started using the CPU for 198ms burst [Q O C J G I F N E D P L K A M]
time 2272ms: Process H completed I/O; added to ready queue [Q O C J G I F N E D P L K A M H]
time 2450ms: Process B completed a CPU burst; 19 bursts to go [Q O C J G I F N E D P L K A M H]
time 2450ms: Process B switching out of CPU; will block on I/O until time 2565ms [Q O C J G I F N E D P L K A M H]
time 2454ms: Process O started using the CPU for 106ms burst [Q C J G I F N E D P L K A M H]
time 2560ms: Process O completed a CPU burst; 29 bursts to go [Q C J G I F N E D P L K A M H]
time 2560ms: Process O switching out of CPU; will block on I/O until time 2811ms [Q C J G I F N E D P L K A M H]
time 2564ms: Process C started using the CPU for 117ms burst [Q J G I F N E D P L K A M H]
time 2565ms: Process B completed I/O; added to ready queue [Q J G I F N E D P L K A M H B]
time 2681ms: Process C completed a CPU burst; 2 bursts to go [Q J G I F N E D P L K A M H B]
time 2681ms: Process C switching out of CPU; will block on I/O until time 2700ms [Q J G I F N E D P L K A M H B]
time 2685ms: Process J started using the CPU for 28ms burst [Q G I F N E D P L K A M H B]
time 2700ms: Process C completed I/O; added to ready queue [Q G I F N E D P L K A M H B C]
time 2713ms: Process J completed a CPU burst; 7 bursts to go [Q G I F N E D P L K A M H B C]
time 2713ms: Process J switching out of CPU; will block on I/O until time 2737ms [Q G I F N E D P L K A M H B C]
time 2717ms: Process G started using the CPU for 40ms burst [Q I F N E D P L K A M H B C]
time 2737ms: Process J completed I/O; added to ready queue [Q I F N E D P L K A M H B C J]
time 2757ms: Process G completed a CPU burst; 78 bursts to go [Q I F N E D P L K A M H B C J]
time 2757ms: Process G switching out of CPU; will block on I/O until time 2765ms [Q I F N E D P L K A M H B C J]
time 2761ms: Process I started using the CPU for 16ms burst [Q F N E D P L K A M H B C J]
time 2765ms: Process G completed I/O; added to ready queue [Q F N E D P L K A M H B C J G]
time 2777ms: Process I completed a CPU burst; 75 bursts to go [Q F N E D P L K A M H B C J G]
time 2777ms: Process I switching out of CPU; will block on I/O until time 2955ms [Q F N E D P L K A M H B C J G]
time 2781ms: Process F started using the CPU for 39ms burst [Q N E D P L K A M H B C J G]
time 2811ms: Process O completed I/O; added to ready queue [Q N E D P L K A M H B C J G O]
time 2820ms: Process F completed a CPU burst; 32 bursts to go [Q N E D P L K A M H B C J G O]
time 2820ms: Process F switching out of CPU; will block on I/O until time 2887ms [Q N E D P L K A M H B C J G O]
time 2824ms: Process N started using the CPU for 132ms burst [Q E D P L K A M H B C J G O]
time 2887ms: Process F completed I/O; added to ready queue [Q E D P L K A M H B C J G O F]
time 2955ms: Process I completed I/O; added to ready queue [Q E D P L K A M H B C J G O F I]
time 2956ms: Process N completed a CPU burst; 29 bursts to go [Q E D P L K A M H B C J G O F I]
time 2956ms: Process N switching out of CPU; will block on I/O until time 3118ms [Q E D P L K A M H B C J G O F I]
time 2960ms: Process E started using the CPU for 44ms burst [Q D P L K A M H B C J G O F I]
time 3004ms: Process E completed a CPU burst; 53 bursts to go [Q D P L K A M H B C J G O F I]
time 3004ms: Process E switching out of CPU; will block on I/O until time 3062ms [Q D P L K A M H B C J G O F I]
time 3008ms: Process D started using the CPU for 211ms burst [Q P L K A M H B C J G O F I]
time 3062ms: Process E completed I/O; added to ready queue [Q P L K A M H B C J G O F I E]
time 3118ms: Process N completed I/O; added to ready queue [Q P L K A M H B C J G O F I E N]
time 3219ms: Process D completed a CPU burst; 9 bursts to go [Q P L K A M H B C J G O F I E N]
time 3219ms: Process D switching out of CPU; will block on I/O until time 3435ms [Q P L K A M H B C J G O F I E N]
time 3223ms: Process P started using the CPU for 52ms burst [Q L K A M H B C J G O F I E N]
time 3275ms: Process P completed a CPU burst; 14 bursts to go [Q L K A M H B C J G O F I E N]
time 3275ms: Process P switching out of CPU; will block on I/O until time 3386ms [Q L K A M H B C J G O F I E N]
time 3279ms: Process L started using the CPU for 4ms burst [Q K A M H B C J G O F I E N]
time 3283ms: Process L completed a CPU burst; 5 bursts to go [Q K A M H B C J G O F I E N]
time 3283ms: Process L switching out of CPU; will block on I/O until time 3327ms [Q K A M H B C J G O F I E N]
time 3287ms: Process K started using the CPU for 6ms burst [Q A M H B C J G O F I E N]
time 3293ms: Process K completed a CPU burst; 10 bursts to go [Q A M H B C J G O F I E N]
time 3293ms: Process K switching out of CPU; will block on I/O until time 3365ms [Q A M H B C J G O F I E N]
time 3297ms: Process A started using the CPU for 39ms burst [Q M H B C J G O F I E N]
time 3327ms: Process L completed I/O; added to ready queue [Q M H B C J G O F I E N L]
time 3336ms: Process A completed a CPU burst; 13 bursts to go [Q M H B C J G O F I E N L]
time 3336ms: Process A switching out of CPU; will block on I/O until time 3388ms [Q M H B C J G O F I E N L]
time 3340ms: Process M started using the CPU for 79ms burst [Q H B C J G O F I E N L]
time 3365ms: Process K completed I/O; added to ready queue [Q H B C J G O F I E N L K]
time 3386ms: Process P completed I/O; added to ready queue [Q H B C J G O F I E N L K P]
time 3388ms: Process A completed I/O; added to ready queue [Q H B C J G O F I E N L K P A]
time 3419ms: Process M completed a CPU burst; 45 bursts to go [Q H B C J G O F I E N L K P A]
time 3419ms: Process M switching out of CPU; will block on I/O until time 3535ms [Q H B C J G O F I E N L K P A]
time 3423ms: Process H started using the CPU for 72ms burst [Q B C J G O F I E N L K P A]
time 3435ms: Process D completed I/O; added to ready queue [Q B C J G O F I E N L K P A D]
time 3495ms: Process H completed a CPU burst; 80 bursts to go [Q B C J G O F I E N L K P A D]
time 3495ms: Process H switching out of CPU; will block on I/O until time 3539ms [Q B C J G O F I E N L K P A D]
time 3499ms: Process B started using the CPU for 208ms burst [Q C J G O F I E N L K P A D]
time 3535ms: Process M completed I/O; added to ready queue [Q C J G O F I E N L K P A D M]
time 3539ms: Process H completed I/O; added to ready queue [Q C J G O F I E N L K P A D M H]
time 3707ms: Process B completed a CPU burst; 18 bursts to go [Q C J G O F I E N L K P A D M H]
time 3707ms: Process B switching out of CPU; will block on I/O until time 3871ms [Q C J G O F I E N L K P A D M H]
time 3711ms: Process C started using the CPU for 85ms burst [Q J G O F I E N L K P A D M H]
time 3796ms: Process C completed a CPU burst; 1 burst to go [Q J G O F I E N L K P A D M H]
time 3796ms: Process C switching out of CPU; will block on I/O until time 3819ms [Q J G O F I E N L K P A D M H]
time 3800ms: Process J started using the CPU for 120ms burst [Q G O F I E N L K P A D M H]
time 3819ms: Process C completed I/O; added to ready queue [Q G O F I E N L K P A D M H C]
time 3871ms: Process B completed I/O; added to ready queue [Q G O F I E N L K P A D M H C B]
time 3920ms: Process J completed a CPU burst; 6 bursts to go [Q G O F I E N L K P A D M H C B]
time 3920ms: Process J switching out of CPU; will block on I/O until time 3978ms [Q G O F I E N L K P A D M H C B]
time 3924ms: Process G started using the CPU for 65ms burst [Q O F I E N L K P A D M H C B]
time 3978ms: Process J completed I/O; added to ready queue [Q O F I E N L K P A D M H C B J]
time 3989ms: Process G completed a CPU burst; 77 bursts to go [Q O F I E N L K P A D M H C B J]
time 3989ms: Process G switching out of CPU; will block on I/O until time 4035ms [Q O F I E N L K P A D M H C B J]
time 3993ms: Process O started using the CPU for 57ms burst [Q F I E N L K P A D M H C B J]
time 4035ms: Process G completed I/O; added to ready queue [Q F I E N L K P A D M H C B J G]
time 4050ms: Process O completed a CPU burst; 28 bursts to go [Q F I E N L K P A D M H C B J G]
time 4050ms: Process O switching out of CPU; will block on I/O until time 4089ms [Q F I E N L K P A D M H C B J G]
time 4054ms: Process F started using the CPU for 195ms burst [Q I E N L K P A D M H C B J G]
time 4089ms: Process O completed I/O; added to ready queue [Q I E N L K P A D M H C B J G O]
time 4249ms: Process F completed a CPU burst; 31 bursts to go [Q I E N L K P A D M H C B J G O]
time 4249ms: Process F switching out of CPU; will block on I/O until time 4252ms [Q I E N L K P A D M H C B J G O]
time 4252ms: Process F completed I/O; added to ready queue [Q E N L K P A D M H C B J G O F]
time 4253ms: Process I started using the CPU for 26ms burst [Q E N L K P A D M H C B J G O F]
time 4279ms: Process I completed a CPU burst; 74 bursts to go [Q E N L K P A D M H C B J G O F]
time 4279ms: Process I switching out of CPU; will block on I/O until time 4344ms [Q E N L K P A D M H C B J G O F]
time 4283ms: Process E started using the CPU for 2ms burst [Q N L K P A D M H C B J G O F]
time 4285ms: Process E completed a CPU burst; 52 bursts to go [Q N L K P A D M H C B J G O F]
time 4285ms: Process E switching out of CPU; will block on I/O until time 4312ms [Q N L K P A D M H C B J G O F]
time 4289ms: Process N started using the CPU for 17ms burst [Q L K P A D M H C B J G O F]
time 4306ms: Process N completed a CPU burst; 28 bursts to go [Q L K P A D M H C B J G O F]
time 4306ms: Process N switching out of CPU; will block on I/O until time 4383ms [Q L K P A D M H C B J G O F]
time 4310ms: Process L started using the CPU for 69ms burst [Q K P A D M H C B J G O F]
time 4312ms: Process E completed I/O; added to ready queue [Q K P A D M H C B J G O F E]
time 4344ms: Process I completed I/O; added to ready queue [Q K P A D M H C B J G O F E I]
time 4379ms: Process L completed a CPU burst; 4 bursts to go [Q K P A D M H C B J G O F E I]
time 4379ms: Process L switching out of CPU; will block on I/O until time 4476ms [Q K P A D M H C B J G O F E I]
time 4383ms: Process K started using the CPU for 6ms burst [Q P A D M H C B J G O F E I]
time 4383ms: Process N completed I/O; added to ready queue [Q P A D M H C B J G O F E I N]
time 4389ms: Process K completed a CPU burst; 9 bursts to go [Q P A D M H C B J G O F E I N]
time 4389ms: Process K switching out of CPU; will block on I/O until time 4466ms [Q P A D M H C B J G O F E I N]
time 4393ms: Process P started using the CPU for 56ms burst [Q A D M H C B J G O F E I N]
time 4449ms: Process P completed a CPU burst; 13 bursts to go [Q A D M H C B J G O F E I N]
time 4449ms: Process P switching out of CPU; will block on I/O until time 4572ms [Q A D M H C B J G O F E I N]
time 4453ms: Process A started using the CPU for 47ms burst [Q D M H C B J G O F E I N]
time 4466ms: Process K completed I/O; added to ready queue [Q D M H C B J G O F E I N K]
time 4476ms: Process L completed I/O; added to ready queue [Q D M H C B J G O F E I N K L]
time 4500ms: Process A completed a CPU burst; 12 bursts to go [Q D M H C B J G O F E I N K L]
time 4500ms: Process A switching out of CPU; will block on I/O until time 4504ms [Q D M H C B J G O F E I N K L]
time 4504ms: Process D started using the CPU for 9ms burst [Q M H C B J G O F E I N K L]
time 4504ms: Process A completed I/O; added to ready queue [Q M H C B J G O F E I N K L A]
time 4513ms: Process D completed a CPU burst; 8 bursts to go [Q M H C B J G O F E I N K L A]
time 4513ms: Process D switching out of CPU; will block on I/O until time 4553ms [Q M H C B J G O F E I N K L A]
time 4517ms: Process M started using the CPU for 18ms burst [Q H C B J G O F E I N K L A]
time 4535ms: Process M completed a CPU burst; 44 bursts to go [Q H C B J G O F E I N K L A]
time 4535ms: Process M switching out of CPU; will block on I/O until time 4734ms [Q H C B J G O F E I N K L A]
time 4539ms: Process H started using the CPU for 12ms burst [Q C B J G O F E I N K L A]
time 4551ms: Process H completed a CPU burst; 79 bursts to go [Q C B J G O F E I N K L A]
time 4551ms: Process H switching out of CPU; will block on I/O until time 4566ms [Q C B J G O F E I N K L A]
time 4553ms: Process D completed I/O; added to ready queue [Q C B J G O F E I N K L A D]
time 4555ms: Process C started using the CPU for 79ms burst [Q B J G O F E I N K L A D]
time 4566ms: Process H completed I/O; added to ready queue [Q B J G O F E I N K L A D H]
time 4572ms: Process P completed I/O; added to ready queue [Q B J G O F E I N K L A D H P]
time 4634ms: Process C terminated [Q B J G O F E I N K L A D H P]
time 4638ms: Process B started using the CPU for 50ms burst [Q J G O F E I N K L A D H P]
time 4688ms: Process B completed a CPU burst; 17 bursts to go [Q J G O F E I N K L A D H P]
time 4688ms: Process B switching out of CPU; will block on I/O until time 4736ms [Q J G O F E I N K L A D H P]
time 4692ms: Process J started using the CPU for 31ms burst [Q G O F E I N K L A D H P]
time 4723ms: Process J completed a CPU burst; 5 bursts to go [Q G O F E I N K L A D H P]
time 4723ms: Process J switching out of CPU; will block on I/O until time 4811ms [Q G O F E I N K L A D H P]
time 4727ms: Process G started using the CPU for 13ms burst [Q O F E I N K L A D H P]
time 4734ms: Process M completed I/O; added to ready queue [Q O F E I N K L A D H P M]
time 4736ms: Process B completed I/O; added to ready queue [Q O F E I N K L A D H P M B]
time 4740ms: Process G completed a CPU burst; 76 bursts to go [Q O F E I N K L A D H P M B]
time 4740ms: Process G switching out of CPU; will block on I/O until time 4780ms [Q O F E I N K L A D H P M B]
time 4744ms: Process O started using the CPU for 13ms burst [Q F E I N K L A D H P M B]
time 4757ms: Process O completed a CPU burst; 27 bursts to go [Q F E I N K L A D H P M B]
time 4757ms: Process O switching out of CPU; will block on I/O until time 4892ms [Q F E I N K L A D H P M B]
time 4761ms: Process F started using the CPU for 72ms burst [Q E I N K L A D H P M B]
time 4780ms: Process G completed I/O; added to ready queue [Q E I N K L A D H P M B G]
time 4811ms: Process J completed I/O; added to ready queue [Q E I N K L A D H P M B G J]
time 4833ms: Process F completed a CPU burst; 30 bursts to go [Q E I N K L A D H P M B G J]
time 4833ms: Process F switching out of CPU; will block on I/O until time 4861ms [Q E I N K L A D H P M B G J]
time 4837ms: Process E started using the CPU for 42ms burst [Q I N K L A D H P M B G J]
time 4861ms: Process F completed I/O; added to ready queue [Q I N K L A D H P M B G J F]
time 4879ms: Process E completed a CPU burst; 51 bursts to go [Q I N K L A D H P M B G J F]
time 4879ms: Process E switching out of CPU; will block on I/O until time 4886ms [Q I N K L A D H P M B G J F]
time 4883ms: Process I started using the CPU for 45ms burst [Q N K L A D H P M B G J F]
time 4886ms: Process E completed I/O; added to ready queue [Q N K L A D H P M B G J F E]
time 4892ms: Process O completed I/O; added to ready queue [Q N K L A D H P M B G J F E O]
time 4928ms: Process I completed a CPU burst; 73 bursts to go [Q N K L A D H P M B G J F E O]
time 4928ms: Process I switching out of CPU; will block on I/O until time 4960ms [Q N K L A D H P M B G J F E O]
time 4932ms: Process N started using the CPU for 71ms burst [Q K L A D H P M B G J F E O]
time 4960ms: Process I completed I/O; added to ready queue [Q K L A D H P M B G J F E O I]
time 5003ms: Process N completed a CPU burst; 27 bursts to go [Q K L A D H P M B G J F E O I]
time 5003ms: Process N switching out of CPU; will block on I/O until time 5199ms [Q K L A D H P M B G J F E O I]
time 5007ms: Process K started using the CPU for 157ms burst [Q L A D H P M B G J F E O I]
time 5164ms: Process K completed a CPU burst; 8 bursts to go [Q L A D H P M B G J F E O I]
time 5164ms: Process K switching out of CPU; will block on I/O until time 5182ms [Q L A D H P M B G J F E O I]
time 5168ms: Process L started using the CPU for 25ms burst [Q A D H P M B G J F E O I]
time 5182ms: Process K completed I/O; added to ready queue [Q A D H P M B G J F E O I K]
time 5193ms: Process L completed a CPU burst; 3 bursts to go [Q A D H P M B G J F E O I K]
time 5193ms: Process L switching out of CPU; will block on I/O until time 5314ms [Q A D H P M B G J F E O I K]
time 5197ms: Process A started using the CPU for 137ms burst [Q D H P M B G J F E O I K]
time 5199ms: Process N completed I/O; added to ready queue [Q D H P M B G J F E O I K N]
time 5314ms: Process L completed I/O; added to ready queue [Q D H P M B G J F E O I K N L]
time 5334ms: Process A completed a CPU burst; 11 bursts to go [Q D H P M B G J F E O I K N L]
time 5334ms: Process A switching out of CPU; will block on I/O until time 5360ms [Q D H P M B G J F E O I K N L]
time 5338ms: Process D started using the CPU for 4ms burst [Q H P M B G J F E O I K N L]
time 5342ms: Process D completed a CPU burst; 7 bursts to go [Q H P M B G J F E O I K N L]
time 5342ms: Process D switching out of CPU; will block on I/O until time 5392ms [Q H P M B G J F E O I K N L]
time 5346ms: Process H started using the CPU for 41ms burst [Q P M B G J F E O I K N L]
time 5360ms: Process A completed I/O; added to ready queue [Q P M B G J F E O I K N L A]
time 5387ms: Process H completed a CPU burst; 78 bursts to go [Q P M B G J F E O I K N L A]
time 5387ms: Process H switching out of CPU; will block on I/O until time 5410ms [Q P M B G J F E O I K N L A]
time 5391ms: Process P started using the CPU for 155ms burst [Q M B G J F E O I K N L A]
time 5392ms: Process D completed I/O; added to ready queue [Q M B G J F E O I K N L A D]
time 5410ms: Process H completed I/O; added to ready queue [Q M B G J F E O I K N L A D H]
time 5546ms: Process P completed a CPU burst; 12 bursts to go [Q M B G J F E O I K N L A D H]
time 5546ms: Process P switching out of CPU; will block on I/O until time 5666ms [Q M B G J F E O I K N L A D H]
time 5550ms: Process M started using the CPU for 66ms burst [Q B G J F E O I K N L A D H]
time 5616ms: Process M completed a CPU burst; 43 bursts to go [Q B G J F E O I K N L A D H]
time 5616ms: Process M switching out of CPU; will block on I/O until time 5799ms [Q B G J F E O I K N L A D H]
time 5620ms: Process B started using the CPU for 82ms burst [Q G J F E O I K N L A D H]
time 5666ms: Process P completed I/O; added to ready queue [Q G J F E O I K N L A D H P]
time 5702ms: Process B completed a CPU burst; 16 bursts to go [Q G J F E O I K N L A D H P]
time 5702ms: Process B switching out of CPU; will block on I/O until time 5720ms [Q G J F E O I K N L A D H P]
time 5706ms: Process G started using the CPU for 128ms burst [Q J F E O I K N L A D H P]
time 5720ms: Process B completed I/O; added to ready queue [Q J F E O I K N L A D H P B]
time 5799ms: Process M completed I/O; added to ready queue [Q J F E O I K N L A D H P B M]
time 5834ms: Process G completed a CPU burst; 75 bursts to go [Q J F E O I K N L A D H P B M]
time 5834ms: Process G switching out of CPU; will block on I/O until time 6058ms [Q J F E O I K N L A D H P B M]
time 5838ms: Process J started using the CPU for 32ms burst [Q F E O I K N L A D H P B M]
time 5870ms: Process J completed a CPU burst; 4 bursts to go [Q F E O I K N L A D H P B M]
time 5870ms: Process J switching out of CPU; will block on I/O until time 5885ms [Q F E O I K N L A D H P B M]
time 5874ms: Process F started using the CPU for 8ms burst [Q E O I K N L A D H P B M]
time 5882ms: Process F completed a CPU burst; 29 bursts to go [Q E O I K N L A D H P B M]
time 5882ms: Process F switching out of CPU; will block on I/O until time 5917ms [Q E O I K N L A D H P B M]
time 5885ms: Process J completed I/O; added to ready queue [Q O I K N L A D H P B M J]
time 5886ms: Process E started using the CPU for 108ms burst [Q O I K N L A D H P B M J]
time 5917ms: Process F completed I/O; added to ready queue [Q O I K N L A D H P B M J F]
time 5994ms: Process E completed a CPU burst; 50 bursts to go [Q O I K N L A D H P B M J F]
time 5994ms: Process E switching out of CPU; will block on I/O until time 6005ms [Q O I K N L A D H P B M J F]
time 5998ms: Process O started using the CPU for 130ms burst [Q I K N L A D H P B M J F]
time 6005ms: Process E completed I/O; added to ready queue [Q I K N L A D H P B M J F E]
time 6058ms: Process G completed I/O; added to ready queue [Q I K N L A D H P B M J F E G]
time 6128ms: Process O completed a CPU burst; 26 bursts to go [Q I K N L A D H P B M J F E G]
time 6128ms: Process O switching out of CPU; will block on I/O until time 6201ms [Q I K N L A D H P B M J F E G]
time 6132ms: Process I started using the CPU for 38ms burst [Q K N L A D H P B M J F E G]
time 6170ms: Process I completed a CPU burst; 72 bursts to go [Q K N L A D H P B M J F E G]
time 6170ms: Process I switching out of CPU; will block on I/O until time 6230ms [Q K N L A D H P B M J F E G]
time 6174ms: Process K started using the CPU for 104ms burst [Q N L A D H P B M J F E G]
time 6201ms: Process O completed I/O; added to ready queue [Q N L A D H P B M J F E G O]
time 6230ms: Process I completed I/O; added to ready queue [Q N L A D H P B M J F E G O I]
time 6278ms: Process K completed a CPU burst; 7 bursts to go [Q N L A D H P B M J F E G O I]
time 6278ms: Process K switching out of CPU; will block on I/O until time 6425ms [Q N L A D H P B M J F E G O I]
time 6282ms: Process N started using the CPU for 27ms burst [Q L A D H P B M J F E G O I]
time 6309ms: Process N completed a CPU burst; 26 bursts to go [Q L A D H P B M J F E G O I]
time 6309ms: Process N switching out of CPU; will block on I/O until time 6338ms [Q L A D H P B M J F E G O I]
time 6313ms: Process L started using the CPU for 2ms burst [Q A D H P B M J F E G O I]
time 6315ms: Process L completed a CPU burst; 2 bursts to go [Q A D H P B M J F E G O I]
time 6315ms: Process L switching out of CPU; will block on I/O until time 6354ms [Q A D H P B M J F E G O I]
time 6319ms: Process A started using the CPU for 64ms burst [Q D H P B M J F E G O I]
time 6338ms: Process N completed I/O; added to ready queue [Q D H P B M J F E G O I N]
time 6354ms: Process L completed I/O; added to ready queue [Q D H P B M J F E G O I N L]
time 6383ms: Process A completed a CPU burst; 10 bursts to go [Q D H P B M J F E G O I N L]
time 6383ms: Process A switching out of CPU; will block on I/O until time 6400ms [Q D H P B M J F E G O I N L]
time 6387ms: Process D started using the CPU for 149ms burst [Q H P B M J F E G O I N L]
time 6400ms: Process A completed I/O; added to ready queue [Q H P B M J F E G O I N L A]
time 6425ms: Process K completed I/O; added to ready queue [Q H P B M J F E G O I N L A K]
time 6536ms: Process D completed a CPU burst; 6 bursts to go [Q H P B M J F E G O I N L A K]
time 6536ms: Process D switching out of CPU; will block on I/O until time 6619ms [Q H P B M J F E G O I N L A K]
time 6540ms: Process H started using the CPU for 160ms burst [Q P B M J F E G O I N L A K]
time 6619ms: Process D completed I/O; added to ready queue [Q P B M J F E G O I N L A K D]
time 6700ms: Process H completed a CPU burst; 77 bursts to go [Q P B M J F E G O I N L A K D]
time 6700ms: Process H switching out of CPU; will block on I/O until time 6762ms [Q P B M J F E G O I N L A K D]
time 6704ms: Process P started using the CPU for 4ms burst [Q B M J F E G O I N L A K D]
time 6708ms: Process P completed a CPU burst; 11 bursts to go [Q B M J F E G O I N L A K D]
time 6708ms: Process P switching out of CPU; will block on I/O until time 6889ms [Q B M J F E G O I N L A K D]
time 6712ms: Process B started using the CPU for 7ms burst [Q M J F E G O I N L A K D]
time 6719ms: Process B completed a CPU burst; 15 bursts to go [Q M J F E G O I N L A K D]
time 6719ms: Process B switching out of CPU; will block on I/O until time 6751ms [Q M J F E G O I N L A K D]
time 6723ms: Process M started using the CPU for 103ms burst [Q J F E G O I N L A K D]
time 6751ms: Process B completed I/O; added to ready queue [Q J F E G O I N L A K D B]
time 6762ms: Process H completed I/O; added to ready queue [Q J F E G O I N L A K D B H]
time 6826ms: Process M completed a CPU burst; 42 bursts to go [Q J F E G O I N L A K D B H]
time 6826ms: Process M switching out of CPU; will block on I/O until time 6868ms [Q J F E G O I N L A K D B H]
time 6830ms: Process J started using the CPU for 23ms burst [Q F E G O I N L A K D B H]
time 6853ms: Process J completed a CPU burst; 3 bursts to go [Q F E G O I N L A K D B H]
time 6853ms: Process J switching out of CPU; will block on I/O until time 6871ms [Q F E G O I N L A K D B H]
time 6857ms: Process F started using the CPU for 230ms burst [Q E G O I N L A K D B H]
time 6868ms: Process M completed I/O; added to ready queue [Q E G O I N L A K D B H M]
time 6871ms: Process J completed I/O; added to ready queue [Q E G O I N L A K D B H M J]
time 6889ms: Process P completed I/O; added to ready queue [Q E G O I N L A K D B H M J P]
time 7087ms: Process F completed a CPU burst; 28 bursts to go [Q E G O I N L A K D B H M J P]
time 7087ms: Process F switching out of CPU; will block on I/O until time 7092ms [Q E G O I N L A K D B H M J P]
time 7091ms: Process E started using the CPU for 6ms burst [Q G O I N L A K D B H M J P]
time 7092ms: Process F completed I/O; added to ready queue [Q G O I N L A K D B H M J P F]
time 7097ms: Process E completed a CPU burst; 49 bursts to go [Q G O I N L A K D B H M J P F]
time 7097ms: Process E switching out of CPU; will block on I/O until time 7131ms [Q G O I N L A K D B H M J P F]
time 7101ms: Process G started using the CPU for 15ms burst [Q O I N L A K D B H M J P F]
time 7116ms: Process G completed a CPU burst; 74 bursts to go [Q O I N L A K D B H M J P F]
time 7116ms: Process G switching out of CPU; will block on I/O until time 7212ms [Q O I N L A K D B H M J P F]
time 7120ms: Process O started using the CPU for 68ms burst [Q I N L A K D B H M J P F]
time 7131ms: Process E completed I/O; added to ready queue [Q I N L A K D B H M J P F E]
time 7188ms: Process O completed a CPU burst; 25 bursts to go [Q I N L A K D B H M J P F E]
time 7188ms: Process O switching out of CPU; will block on I/O until time 7307ms [Q I N L A K D B H M J P F E]
time 7192ms: Process I started using the CPU for 79ms burst [Q N L A K D B H M J P F E]
time 7212ms: Process G completed I/O; added to ready queue [Q N L A K D B H M J P F E G]
time 7271ms: Process I completed a CPU burst; 71 bursts to go [Q N L A K D B H M J P F E G]
time 7271ms: Process I switching out of CPU; will block on I/O until time 7389ms [Q N L A K D B H M J P F E G]
time 7275ms: Process N started using the CPU for 57ms burst [Q L A K D B H M J P F E G]
time 7307ms: Process O completed I/O; added to ready queue [Q L A K D B H M J P F E G O]
time 7332ms: Process N completed a CPU burst; 25 bursts to go [Q L A K D B H M J P F E G O]
time 7332ms: Process N switching out of CPU; will block on I/O until time 7344ms [Q L A K D B H M J P F E G O]
time 7336ms: Process L started using the CPU for 164ms burst [Q A K D B H M J P F E G O]
time 7344ms: Process N completed I/O; added to ready queue [Q A K D B H M J P F E G O N]
time 7389ms: Process I completed I/O; added to ready queue [Q A K D B H M J P F E G O N I]
time 7500ms: Process L completed a CPU burst; 1 burst to go [Q A K D B H M J P F E G O N I]
time 7500ms: Process L switching out of CPU; will block on I/O until time 7552ms [Q A K D B H M J P F E G O N I]
time 7504ms: Process A started using the CPU for 68ms burst [Q K D B H M J P F E G O N I]
time 7552ms: Process L completed I/O; added to ready queue [Q K D B H M J P F E G O N I L]
time 7572ms: Process A completed a CPU burst; 9 bursts to go [Q K D B H M J P F E G O N I L]
time 7572ms: Process A switching out of CPU; will block on I/O until time 7638ms [Q K D B H M J P F E G O N I L]
time 7576ms: Process K started using the CPU for 86ms burst [Q D B H M J P F E G O N I L]
time 7638ms: Process A completed I/O; added to ready queue [Q D B H M J P F E G O N I L A]
time 7662ms: Process K completed a CPU burst; 6 bursts to go [Q D B H M J P F E G O N I L A]
time 7662ms: Process K switching out of CPU; will block on I/O until time 7692ms [Q D B H M J P F E G O N I L A]
time 7666ms: Process D started using the CPU for 52ms burst [Q B H M J P F E G O N I L A]
time 7692ms: Process K completed I/O; added to ready queue [Q B H M J P F E G O N I L A K]
time 7718ms: Process D completed a CPU burst; 5 bursts to go [Q B H M J P F E G O N I L A K]
time 7718ms: Process D switching out of CPU; will block on I/O until time 7723ms [Q B H M J P F E G O N I L A K]
time 7722ms: Process B started using the CPU for 52ms burst [Q H M J P F E G O N I L A K]
time 7723ms: Process D completed I/O; added to ready queue [Q H M J P F E G O N I L A K D]
time 7774ms: Process B completed a CPU burst; 14 bursts to go [Q H M J P F E G O N I L A K D]
time 7774ms: Process B switching out of CPU; will block on I/O until time 7788ms [Q H M J P F E G O N I L A K D]
time 7778ms: Process H started using the CPU for 28ms burst [Q M J P F E G O N I L A K D]
time 7788ms: Process B completed I/O; added to ready queue [Q M J P F E G O N I L A K D B]
time 7806ms: Process H completed a CPU burst; 76 bursts to go [Q M J P F E G O N I L A K D B]
time 7806ms: Process H switching out of CPU; will block on I/O until time 7904ms [Q M J P F E G O N I L A K D B]
time 7810ms: Process M started using the CPU for 171ms burst [Q J P F E G O N I L A K D B]
time 7904ms: Process H completed I/O; added to ready queue [Q J P F E G O N I L A K D B H]
time 7981ms: Process M completed a CPU burst; 41 bursts to go [Q J P F E G O N I L A K D B H]
time 7981ms: Process M switching out of CPU; will block on I/O until time 8004ms [Q J P F E G O N I L A K D B H]
time 7985ms: Process J started using the CPU for 51ms burst [Q P F E G O N I L A K D B H]
time 8004ms: Process M completed I/O; added to ready queue [Q P F E G O N I L A K D B H M]
time 8036ms: Process J completed a CPU burst; 2 bursts to go [Q P F E G O N I L A K D B H M]
time 8036ms: Process J switching out of CPU; will block on I/O until time 8135ms [Q P F E G O N I L A K D B H M]
time 8040ms: Process P started using the CPU for 105ms burst [Q F E G O N I L A K D B H M]
time 8135ms: Process J completed I/O; added to ready queue [Q F E G O N I L A K D B H M J]
time 8145ms: Process P completed a CPU burst; 10 bursts to go [Q F E G O N I L A K D B H M J]
time 8145ms: Process P switching out of CPU; will block on I/O until time 8206ms [Q F E G O N I L A K D B H M J]
time 8149ms: Process F started using the CPU for 33ms burst [Q E G O N I L A K D B H M J]
time 8182ms: Process F completed a CPU burst; 27 bursts to go [Q E G O N I L A K D B H M J]
time 8182ms: Process F switching out of CPU; will block on I/O until time 8240ms [Q E G O N I L A K D B H M J]
time 8186ms: Process E started using the CPU for 112ms burst [Q G O N I L A K D B H M J]
time 8206ms: Process P completed I/O; added to ready queue [Q G O N I L A K D B H M J P]
time 8240ms: Process F completed I/O; added to ready queue [Q G O N I L A K D B H M J P F]
time 8298ms: Process E completed a CPU burst; 48 bursts to go [Q G O N I L A K D B H M J P F]
time 8298ms: Process E switching out of CPU; will block on I/O until time 8411ms [Q G O N I L A K D B H M J P F]
time 8302ms: Process G started using the CPU for 112ms burst [Q O N I L A K D B H M J P F]
time 8411ms: Process E completed I/O; added to ready queue [Q O N I L A K D B H M J P F E]
time 8414ms: Process G completed a CPU burst; 73 bursts to go [Q O N I L A K D B H M J P F E]
time 8414ms: Process G switching out of CPU; will block on I/O until time 8459ms [Q O N I L A K D B H M J P F E]
time 8418ms: Process O started using the CPU for 136ms burst [Q N I L A K D B H M J P F E]
time 8459ms: Process G completed I/O; added to ready queue [Q N I L A K D B H M J P F E G]
time 8554ms: Process O completed a CPU burst; 24 bursts to go [Q N I L A K D B H M J P F E G]
time 8554ms: Process O switching out of CPU; will block on I/O until time 8661ms [Q N I L A K D B H M J P F E G]
time 8558ms: Process N started using the CPU for 84ms burst [Q I L A K D B H M J P F E G]
time 8642ms: Process N completed a CPU burst; 24 bursts to go [Q I L A K D B H M J P F E G]
time 8642ms: Process N switching out of CPU; will block on I/O until time 8646ms [Q I L A K D B H M J P F E G]
time 8646ms: Process I started using the CPU for 84ms burst [Q L A K D B H M J P F E G]
time 8646ms: Process N completed I/O; added to ready queue [Q L A K D B H M J P F E G N]
time 8661ms: Process O completed I/O; added to ready queue [Q L A K D B H M J P F E G N O]
time 8730ms: Process I completed a CPU burst; 70 bursts to go [Q L A K D B H M J P F E G N O]
time 8730ms: Process I switching out of CPU; will block on I/O until time 8783ms [Q L A K D B H M J P F E G N O]
time 8734ms: Process L started using the CPU for 111ms burst [Q A K D B H M J P F E G N O]
time 8783ms: Process I completed I/O; added to ready queue [Q A K D B H M J P F E G N O I]
time 8845ms: Process L terminated [Q A K D B H M J P F E G N O I]
time 8849ms: Process A started using the CPU for 113ms burst [Q K D B H M J P F E G N O I]
time 8962ms: Process A completed a CPU burst; 8 bursts to go [Q K D B H M J P F E G N O I]
time 8962ms: Process A switching out of CPU; will block on I/O until time 8980ms [Q K D B H M J P F E G N O I]
time 8966ms: Process K started using the CPU for 50ms burst [Q D B H M J P F E G N O I]
time 8980ms: Process A completed I/O; added to ready queue [Q D B H M J P F E G N O I A]
time 9016ms: Process K completed a CPU burst; 5 bursts to go [Q D B H M J P F E G N O I A]
time 9016ms: Process K switching out of CPU; will block on I/O until time 9068ms [Q D B H M J P F E G N O I A]
time 9020ms: Process D started using the CPU for 23ms burst [Q B H M J P F E G N O I A]
time 9043ms: Process D completed a CPU burst; 4 bursts to go [Q B H M J P F E G N O I A]
time 9043ms: Process D switching out of CPU; will block on I/O until time 9239ms [Q B H M J P F E G N O I A]
time 9047ms: Process B started using the CPU for 228ms burst [Q H M J P F E G N O I A]
time 9068ms: Process K completed I/O; added to ready queue [Q H M J P F E G N O I A K]
time 9239ms: Process D completed I/O; added to ready queue [Q H M J P F E G N O I A K D]
time 9275ms: Process B completed a CPU burst; 13 bursts to go [Q H M J P F E G N O I A K D]
time 9275ms: Process B switching out of CPU; will block on I/O until time 9354ms [Q H M J P F E G N O I A K D]
time 9279ms: Process H started using the CPU for 51ms burst [Q M J P F E G N O I A K D]
time 9330ms: Process H completed a CPU burst; 75 bursts to go [Q M J P F E G N O I A K D]
time 9330ms: Process H switching out of CPU; will block on I/O until time 9355ms [Q M J P F E G N O I A K D]
time 9334ms: Process M started using the CPU for 200ms burst [Q J P F E G N O I A K D]
time 9354ms: Process B completed I/O; added to ready queue [Q J P F E G N O I A K D B]
time 9355ms: Process H completed I/O; added to ready queue [Q J P F E G N O I A K D B H]
time 9534ms: Process M completed a CPU burst; 40 bursts to go [Q J P F E G N O I A K D B H]
time 9534ms: Process M switching out of CPU; will block on I/O until time 9667ms [Q J P F E G N O I A K D B H]
time 9538ms: Process J started using the CPU for 216ms burst [Q P F E G N O I A K D B H]
time 9667ms: Process M completed I/O; added to ready queue [Q P F E G N O I A K D B H M]
time 9754ms: Process J completed a CPU burst; 1 burst to go [Q P F E G N O I A K D B H M]
time 9754ms: Process J switching out of CPU; will block on I/O until time 9764ms [Q P F E G N O I A K D B H M]
time 9758ms: Process P started using the CPU for 16ms burst [Q F E G N O I A K D B H M]
time 9764ms: Process J completed I/O; added to ready queue [Q F E G N O I A K D B H M J]
time 9774ms: Process P completed a CPU burst; 9 bursts to go [Q F E G N O I A K D B H M J]
time 9774ms: Process P switching out of CPU; will block on I/O until time 9841ms [Q F E G N O I A K D B H M J]
time 9778ms: Process F started using the CPU for 76ms burst [Q E G N O I A K D B H M J]
time 9841ms: Process P completed I/O; added to ready queue [Q E G N O I A K D B H M J P]
time 9854ms: Process F completed a CPU burst; 26 bursts to go [Q E G N O I A K D B H M J P]
time 9854ms: Process F switching out of CPU; will block on I/O until time 9894ms [Q E G N O I A K D B H M J P]
time 9858ms: Process E started using the CPU for 12ms burst [Q G N O I A K D B H M J P]
time 9870ms: Process E completed a CPU burst; 47 bursts to go [Q G N O I A K D B H M J P]
time 9870ms: Process E switching out of CPU; will block on I/O until time 9917ms [Q G N O I A K D B H M J P]
time 9874ms: Process G started using the CPU for 30ms burst [Q N O I A K D B H M J P]
time 9894ms: Process F completed I/O; added to ready queue [Q N O I A K D B H M J P F]
time 9904ms: Process G completed a CPU burst; 72 bursts to go [Q N O I A K D B H M J P F]
time 9904ms: Process G switching out of CPU; will block on I/O until time 9953ms [Q N O I A K D B H M J P F]
time 9908ms: Process N started using the CPU for 131ms burst [Q O I A K D B H M J P F]
time 9917ms: Process E completed I/O; added to ready queue [Q O I A K D B H M J P F E]
time 9953ms: Process G completed I/O; added to ready queue [Q O I A K D B H M J P F E G]
time 10039ms: Process N completed a CPU burst; 23 bursts to go [Q O I A K D B H M J P F E G]
time 10039ms: Process N switching out of CPU; will block on I/O until time 10064ms [Q O I A K D B H M J P F E G]
time 10043ms: Process O started using the CPU for 69ms burst [Q I A K D B H M J P F E G]
time 10064ms: Process N completed I/O; added to ready queue [Q I A K D B H M J P F E G N]
time 10112ms: Process O completed a CPU burst; 23 bursts to go [Q I A K D B H M J P F E G N]
time 10112ms: Process O switching out of CPU; will block on I/O until time 10189ms [Q I A K D B H M J P F E G N]
time 10116ms: Process I started using the CPU for 27ms burst [Q A K D B H M J P F E G N]
time 10143ms: Process I completed a CPU burst; 69 bursts to go [Q A K D B H M J P F E G N]
time 10143ms: Process I switching out of CPU; will block on I/O until time 10335ms [Q A K D B H M J P F E G N]
time 10147ms: Process A started using the CPU for 11ms burst [Q K D B H M J P F E G N]
time 10158ms: Process A completed a CPU burst; 7 bursts to go [Q K D B H M J P F E G N]
time 10158ms: Process A switching out of CPU; will block on I/O until time 10322ms [Q K D B H M J P F E G N]
time 10162ms: Process K started using the CPU for 4ms burst [Q D B H M J P F E G N]
time 10166ms: Process K completed a CPU burst; 4 bursts to go [Q D B H M J P F E G N]
time 10166ms: Process K switching out of CPU; will block on I/O until time 10228ms [Q D B H M J P F E G N]
time 10170ms: Process D started using the CPU for 76ms burst [Q B H M J P F E G N]
time 10189ms: Process O completed I/O; added to ready queue [Q B H M J P F E G N O]
time 10228ms: Process K completed I/O; added to ready queue [Q B H M J P F E G N O K]
time 10246ms: Process D completed a CPU burst; 3 bursts to go [Q B H M J P F E G N O K]
time 10246ms: Process D switching out of CPU; will block on I/O until time 10321ms [Q B H M J P F E G N O K]
time 10250ms: Process B started using the CPU for 138ms burst [Q H M J P F E G N O K]
time 10321ms: Process D completed I/O; added to ready queue [Q H M J P F E G N O K D]
time 10322ms: Process A completed I/O; added to ready queue [Q H M J P F E G N O K D A]
time 10335ms: Process I completed I/O; added to ready queue [Q H M J P F E G N O K D A I]
time 10388ms: Process B completed a CPU burst; 12 bursts to go [Q H M J P F E G N O K D A I]
time 10388ms: Process B switching out of CPU; will block on I/O until time 10472ms [Q H M J P F E G N O K D A I]
time 10392ms: Process H started using the CPU for 87ms burst [Q M J P F E G N O K D A I]
time 10472ms: Process B completed I/O; added to ready queue [Q M J P F E G N O K D A I B]
time 10479ms: Process H completed a CPU burst; 74 bursts to go [Q M J P F E G N O K D A I B]
time 10479ms: Process H switching out of CPU; will block on I/O until time 10538ms [Q M J P F E G N O K D A I B]
time 10483ms: Process M started using the CPU for 117ms burst [Q J P F E G N O K D A I B]
time 10538ms: Process H completed I/O; added to ready queue [Q J P F E G N O K D A I B H]
time 10600ms: Process M completed a CPU burst; 39 bursts to go [Q J P F E G N O K D A I B H]
time 10600ms: Process M switching out of CPU; will block on I/O until time 10736ms [Q J P F E G N O K D A I B H]
time 10604ms: Process J started using the CPU for 7ms burst [Q P F E G N O K D A I B H]
time 10611ms: Process J terminated [Q P F E G N O K D A I B H]
time 10615ms: Process P started using the CPU for 219ms burst [Q F E G N O K D A I B H]
time 10736ms: Process M completed I/O; added to ready queue [Q F E G N O K D A I B H M]
time 10834ms: Process P completed a CPU burst; 8 bursts to go [Q F E G N O K D A I B H M]
time 10834ms: Process P switching out of CPU; will block on I/O until time 11041ms [Q F E G N O K D A I B H M]
time 10838ms: Process F started using the CPU for 107ms burst [Q E G N O K D A I B H M]
time 10945ms: Process F completed a CPU burst; 25 bursts to go [Q E G N O K D A I B H M]
time 10945ms: Process F switching out of CPU; will block on I/O until time 10965ms [Q E G N O K D A I B H M]
time 10949ms: Process E started using the CPU for 9ms burst [Q G N O K D A I B H M]
time 10958ms: Process E completed a CPU burst; 46 bursts to go [Q G N O K D A I B H M]
time 10958ms: Process E switching out of CPU; will block on I/O until time 11027ms [Q G N O K D A I B H M]
time 10962ms: Process G started using the CPU for 50ms burst [Q N O K D A I B H M]
time 10965ms: Process F completed I/O; added to ready queue [Q N O K D A I B H M F]
time 11012ms: Process G completed a CPU burst; 71 bursts to go [Q N O K D A I B H M F]
time 11012ms: Process G switching out of CPU; will block on I/O until time 11234ms [Q N O K D A I B H M F]
time 11016ms: Process N started using the CPU for 222ms burst [Q O K D A I B H M F]
time 11027ms: Process E completed I/O; added to ready queue [Q O K D A I B H M F E]
time 11041ms: Process P completed I/O; added to ready queue [Q O K D A I B H M F E P]
time 11234ms: Process G completed I/O; added to ready queue [Q O K D A I B H M F E P G]
time 11238ms: Process N completed a CPU burst; 22 bursts to go [Q O K D A I B H M F E P G]
time 11238ms: Process N switching out of CPU; will block on I/O until time 11245ms [Q O K D A I B H M F E P G]
time 11242ms: Process O started using the CPU for 6ms burst [Q K D A I B H M F E P G]
time 11245ms: Process N completed I/O; added to ready queue [Q K D A I B H M F E P G N]
time 11248ms: Process O completed a CPU burst; 22 bursts to go [Q K D A I B H M F E P G N]
time 11248ms: Process O switching out of CPU; will block on I/O until time 11414ms [Q K D A I B H M F E P G N]
time 11252ms: Process K started using the CPU for 21ms burst [Q D A I B H M F E P G N]
time 11273ms: Process K completed a CPU burst; 3 bursts to go [Q D A I B H M F E P G N]
time 11273ms: Process K switching out of CPU; will block on I/O until time 11340ms [Q D A I B H M F E P G N]
time 11277ms: Process D started using the CPU for 50ms burst [Q A I B H M F E P G N]
time 11327ms: Process D completed a CPU burst; 2 bursts to go [Q A I B H M F E P G N]
time 11327ms: Process D switching out of CPU; will block on I/O until time 11341ms [Q A I B H M F E P G N]
time 11331ms: Process A started using the CPU for 24ms burst [Q I B H M F E P G N]
time 11340ms: Process K completed I/O; added to ready queue [Q I B H M F E P G N K]
time 11341ms: Process D completed I/O; added to ready queue [Q I B H M F E P G N K D]
time 11355ms: Process A completed a CPU burst; 6 bursts to go [Q I B H M F E P G N K D]
time 11355ms: Process A switching out of CPU; will block on I/O until time 11474ms [Q I B H M F E P G N K D]
time 11359ms: Process I started using the CPU for 70ms burst [Q B H M F E P G N K D]
time 11414ms: Process O completed I/O; added to ready queue [Q B H M F E P G N K D O]
time 11429ms: Process I completed a CPU burst; 68 bursts to go [Q B H M F E P G N K D O]
time 11429ms: Process I switching out of CPU; will block on I/O until time 11585ms [Q B H M F E P G N K D O]
time 11433ms: Process B started using the CPU for 67ms burst [Q H M F E P G N K D O]
time 11474ms: Process A completed I/O; added to ready queue [Q H M F E P G N K D O A]
time 11500ms: Process B completed a CPU burst; 11 bursts to go [Q H M F E P G N K D O A]
time 11500ms: Process B switching out of CPU; will block on I/O until time 11509ms [Q H M F E P G N K D O A]
time 11504ms: Process H started using the CPU for 156ms burst [Q M F E P G N K D O A]
time 11509ms: Process B completed I/O; added to ready queue [Q M F E P G N K D O A B]
time 11585ms: Process I completed I/O; added to ready queue [Q M F E P G N K D O A B I]
time 11660ms: Process H completed a CPU burst; 73 bursts to go [Q M F E P G N K D O A B I]
time 11660ms: Process H switching out of CPU; will block on I/O until time 11718ms [Q M F E P G N K D O A B I]
time 11664ms: Process M started using the CPU for 6ms burst [Q F E P G N K D O A B I]
time 11670ms: Process M completed a CPU burst; 38 bursts to go [Q F E P G N K D O A B I]
time 11670ms: Process M switching out of CPU; will block on I/O until time 11705ms [Q F E P G N K D O A B I]
time 11674ms: Process F started using the CPU for 89ms burst [Q E P G N K D O A B I]
time 11705ms: Process M completed I/O; added to ready queue [Q E P G N K D O A B I M]
time 11718ms: Process H completed I/O; added to ready queue [Q E P G N K D O A B I M H]
time 11763ms: Process F completed a CPU burst; 24 bursts to go [Q E P G N K D O A B I M H]
time 11763ms: Process F switching out of CPU; will block on I/O until time 11848ms [Q E P G N K D O A B I M H]
time 11767ms: Process E started using the CPU for 62ms burst [Q P G N K D O A B I M H]
time 11829ms: Process E completed a CPU burst; 45 bursts to go [Q P G N K D O A B I M H]
time 11829ms: Process E switching out of CPU; will block on I/O until time 11891ms [Q P G N K D O A B I M H]
time 11833ms: Process P started using the CPU for 70ms burst [Q G N K D O A B I M H]
time 11848ms: Process F completed I/O; added to ready queue [Q G N K D O A B I M H F]
time 11891ms: Process E completed I/O; added to ready queue [Q G N K D O A B I M H F E]
time 11903ms: Process P completed a CPU burst; 7 bursts to go [Q G N K D O A B I M H F E]
time 11903ms: Process P switching out of CPU; will block on I/O until time 12032ms [Q G N K D O A B I M H F E]
time 11907ms: Process G started using the CPU for 5ms burst [Q N K D O A B I M H F E]
time 11912ms: Process G completed a CPU burst; 70 bursts to go [Q N K D O A B I M H F E]
time 11912ms: Process G switching out of CPU; will block on I/O until time 12112ms [Q N K D O A B I M H F E]
time 11916ms: Process N started using the CPU for 148ms burst [Q K D O A B I M H F E]
time 12032ms: Process P completed I/O; added to ready queue [Q K D O A B I M H F E P]
time 12064ms: Process N completed a CPU burst; 21 bursts to go [Q K D O A B I M H F E P]
time 12064ms: Process N switching out of CPU; will block on I/O until time 12204ms [Q K D O A B I M H F E P]
time 12068ms: Process K started using the CPU for 120ms burst [Q D O A B I M H F E P]
time 12112ms: Process G completed I/O; added to ready queue [Q D O A B I M H F E P G]
time 12188ms: Process K completed a CPU burst; 2 bursts to go [Q D O A B I M H F E P G]
time 12188ms: Process K switching out of CPU; will block on I/O until time 12259ms [Q D O A B I M H F E P G]
time 12192ms: Process D started using the CPU for 24ms burst [Q O A B I M H F E P G]
time 12204ms: Process N completed I/O; added to ready queue [Q O A B I M H F E P G N]
time 12216ms: Process D completed a CPU burst; 1 burst to go [Q O A B I M H F E P G N]
time 12216ms: Process D switching out of CPU; will block on I/O until time 12243ms [Q O A B I M H F E P G N]
time 12220ms: Process O started using the CPU for 187ms burst [Q A B I M H F E P G N]
time 12243ms: Process D completed I/O; added to ready queue [Q A B I M H F E P G N D]
time 12259ms: Process K completed I/O; added to ready queue [Q A B I M H F E P G N D K]
time 12407ms: Process O completed a CPU burst; 21 bursts to go [Q A B I M H F E P G N D K]
time 12407ms: Process O switching out of CPU; will block on I/O until time 12576ms [Q A B I M H F E P G N D K]
time 12411ms: Process A started using the CPU for 76ms burst [Q B I M H F E P G N D K]
time 12487ms: Process A completed a CPU burst; 5 bursts to go [Q B I M H F E P G N D K]
time 12487ms: Process A switching out of CPU; will block on I/O until time 12517ms [Q B I M H F E P G N D K]
time 12491ms: Process B started using the CPU for 120ms burst [Q I M H F E P G N D K]
time 12517ms: Process A completed I/O; added to ready queue [Q I M H F E P G N D K A]
time 12576ms: Process O completed I/O; added to ready queue [Q I M H F E P G N D K A O]
time 12611ms: Process B completed a CPU burst; 10 bursts to go [Q I M H F E P G N D K A O]
time 12611ms: Process B switching out of CPU; will block on I/O until time 12626ms [Q I M H F E P G N D K A O]
time 12615ms: Process I started using the CPU for 107ms burst [Q M H F E P G N D K A O]
time 12626ms: Process B completed I/O; added to ready queue [Q M H F E P G N D K A O B]
time 12722ms: Process I completed a CPU burst; 67 bursts to go [Q M H F E P G N D K A O B]
time 12722ms: Process I switching out of CPU; will block on I/O until time 12771ms [Q M H F E P G N D K A O B]
time 12726ms: Process M started using the CPU for 141ms burst [Q H F E P G N D K A O B]
time 12771ms: Process I completed I/O; added to ready queue [Q H F E P G N D K A O B I]
time 12867ms: Process M completed a CPU burst; 37 bursts to go [Q H F E P G N D K A O B I]
time 12867ms: Process M switching out of CPU; will block on I/O until time 12891ms [Q H F E P G N D K A O B I]
time 12871ms: Process H started using the CPU for 184ms burst [Q F E P G N D K A O B I]
time 12891ms: Process M completed I/O; added to ready queue [Q F E P G N D K A O B I M]
time 13055ms: Process H completed a CPU burst; 72 bursts to go [Q F E P G N D K A O B I M]
time 13055ms: Process H switching out of CPU; will block on I/O until time 13083ms [Q F E P G N D K A O B I M]
time 13059ms: Process F started using the CPU for 102ms burst [Q E P G N D K A O B I M]
time 13083ms: Process H completed I/O; added to ready queue [Q E P G N D K A O B I M H]
time 13161ms: Process F completed a CPU burst; 23 bursts to go [Q E P G N D K A O B I M H]
time 13161ms: Process F switching out of CPU; will block on I/O until time 13298ms [Q E P G N D K A O B I M H]
time 13165ms: Process E started using the CPU for 213ms burst [Q P G N D K A O B I M H]
time 13298ms: Process F completed I/O; added to ready queue [Q P G N D K A O B I M H F]
time 13378ms: Process E completed a CPU burst; 44 bursts to go [Q P G N D K A O B I M H F]
time 13378ms: Process E switching out of CPU; will block on I/O until time 13573ms [Q P G N D K A O B I M H F]
time 13382ms: Process P started using the CPU for 55ms burst [Q G N D K A O B I M H F]
time 13437ms: Process P completed a CPU burst; 6 bursts to go [Q G N D K A O B I M H F]
time 13437ms: Process P switching out of CPU; will block on I/O until time 13684ms [Q G N D K A O B I M H F]
time 13441ms: Process G started using the CPU for 122ms burst [Q N D K A O B I M H F]
time 13563ms: Process G completed a CPU burst; 69 bursts to go [Q N D K A O B I M H F]
time 13563ms: Process G switching out of CPU; will block on I/O until time 13600ms [Q N D K A O B I M H F]
time 13567ms: Process N started using the CPU for 32ms burst [Q D K A O B I M H F]
time 13573ms: Process E completed I/O; added to ready queue [Q D K A O B I M H F E]
time 13599ms: Process N completed a CPU burst; 20 bursts to go [Q D K A O B I M H F E]
time 13599ms: Process N switching out of CPU; will block on I/O until time 13759ms [Q D K A O B I M H F E]
time 13600ms: Process G completed I/O; added to ready queue [Q D K A O B I M H F E G]
time 13603ms: Process D started using the CPU for 1ms burst [Q K A O B I M H F E G]
time 13604ms: Process D terminated [Q K A O B I M H F E G]
time 13608ms: Process K started using the CPU for 199ms burst [Q A O B I M H F E G]
time 13684ms: Process P completed I/O; added to ready queue [Q A O B I M H F E G P]
time 13759ms: Process N completed I/O; added to ready queue [Q A O B I M H F E G P N]
time 13807ms: Process K completed a CPU burst; 1 burst to go [Q A O B I M H F E G P N]
time 13807ms: Process K switching out of CPU; will block on I/O until time 13874ms [Q A O B I M H F E G P N]
time 13811ms: Process A started using the CPU for 122ms burst [Q O B I M H F E G P N]
time 13874ms: Process K completed I/O; added to ready queue [Q O B I M H F E G P N K]
time 13933ms: Process A completed a CPU burst; 4 bursts to go [Q O B I M H F E G P N K]
time 13933ms: Process A switching out of CPU; will block on I/O until time 13968ms [Q O B I M H F E G P N K]
time 13937ms: Process O started using the CPU for 89ms burst [Q B I M H F E G P N K]
time 13968ms: Process A completed I/O; added to ready queue [Q B I M H F E G P N K A]
time 14026ms: Process O completed a CPU burst; 20 bursts to go [Q B I M H F E G P N K A]
time 14026ms: Process O switching out of CPU; will block on I/O until time 14168ms [Q B I M H F E G P N K A]
time 14030ms: Process B started using the CPU for 49ms burst [Q I M H F E G P N K A]
time 14079ms: Process B completed a CPU burst; 9 bursts to go [Q I M H F E G P N K A]
time 14079ms: Process B switching out of CPU; will block on I/O until time 14123ms [Q I M H F E G P N K A]
time 14083ms: Process I started using the CPU for 21ms burst [Q M H F E G P N K A]
time 14104ms: Process I completed a CPU burst; 66 bursts to go [Q M H F E G P N K A]
time 14104ms: Process I switching out of CPU; will block on I/O until time 14115ms [Q M H F E G P N K A]
time 14108ms: Process M started using the CPU for 13ms burst [Q H F E G P N K A]
time 14115ms: Process I completed I/O; added to ready queue [Q H F E G P N K A I]
time 14121ms: Process M completed a CPU burst; 36 bursts to go [Q H F E G P N K A I]
time 14121ms: Process M switching out of CPU; will block on I/O until time 14135ms [Q H F E G P N K A I]
time 14123ms: Process B completed I/O; added to ready queue [Q H F E G P N K A I B]
time 14125ms: Process H started using the CPU for 2ms burst [Q F E G P N K A I B]
time 14127ms: Process H completed a CPU burst; 71 bursts to go [Q F E G P N K A I B]
time 14127ms: Process H switching out of CPU; will block on I/O until time 14143ms [Q F E G P N K A I B]
time 14131ms: Process F started using the CPU for 147ms burst [Q E G P N K A I B]
time 14135ms: Process M completed I/O; added to ready queue [Q E G P N K A I B M]
time 14143ms: Process H completed I/O; added to ready queue [Q E G P N K A I B M H]
time 14168ms: Process O completed I/O; added to ready queue [Q E G P N K A I B M H O]
time 14278ms: Process F completed a CPU burst; 22 bursts to go [Q E G P N K A I B M H O]
time 14278ms: Process F switching out of CPU; will block on I/O until time 14285ms [Q E G P N K A I B M H O]
time 14282ms: Process E started using the CPU for 54ms burst [Q G P N K A I B M H O]
time 14285ms: Process F completed I/O; added to ready queue [Q G P N K A I B M H O F]
time 14336ms: Process E completed a CPU burst; 43 bursts to go [Q G P N K A I B M H O F]
time 14336ms: Process E switching out of CPU; will block on I/O until time 14433ms [Q G P N K A I B M H O F]
time 14340ms: Process G started using the CPU for 31ms burst [Q P N K A I B M H O F]
time 14371ms: Process G completed a CPU burst; 68 bursts to go [Q P N K A I B M H O F]
time 14371ms: Process G switching out of CPU; will block on I/O until time 14380ms [Q P N K A I B M H O F]
time 14375ms: Process P started using the CPU for 212ms burst [Q N K A I B M H O F]
time 14380ms: Process G completed I/O; added to ready queue [Q N K A I B M H O F G]
time 14433ms: Process E completed I/O; added to ready queue [Q N K A I B M H O F G E]
time 14587ms: Process P completed a CPU burst; 5 bursts to go [Q N K A I B M H O F G E]
time 14587ms: Process P switching out of CPU; will block on I/O until time 14806ms [Q N K A I B M H O F G E]
time 14591ms: Process N started using the CPU for 97ms burst [Q K A I B M H O F G E]
time 14688ms: Process N completed a CPU burst; 19 bursts to go [Q K A I B M H O F G E]
time 14688ms: Process N switching out of CPU; will block on I/O until time 14781ms [Q K A I B M H O F G E]
time 14692ms: Process K started using the CPU for 47ms burst [Q A I B M H O F G E]
time 14739ms: Process K terminated [Q A I B M H O F G E]
time 14743ms: Process A started using the CPU for 9ms burst [Q I B M H O F G E]
time 14752ms: Process A completed a CPU burst; 3 bursts to go [Q I B M H O F G E]
time 14752ms: Process A switching out of CPU; will block on I/O until time 14822ms [Q I B M H O F G E]
time 14756ms: Process I started using the CPU for 179ms burst [Q B M H O F G E]
time 14781ms: Process N completed I/O; added to ready queue [Q B M H O F G E N]
time 14806ms: Process P completed I/O; added to ready queue [Q B M H O F G E N P]
time 14822ms: Process A completed I/O; added to ready queue [Q B M H O F G E N P A]
time 14935ms: Process I completed a CPU burst; 65 bursts to go [Q B M H O F G E N P A]
time 14935ms: Process I switching out of CPU; will block on I/O until time 15037ms [Q B M H O F G E N P A]
time 14939ms: Process B started using the CPU for 134ms burst [Q M H O F G E N P A]
time 15037ms: Process I completed I/O; added to ready queue [Q M H O F G E N P A I]
time 15073ms: Process B completed a CPU burst; 8 bursts to go [Q M H O F G E N P A I]
time 15073ms: Process B switching out of CPU; will block on I/O until time 15107ms [Q M H O F G E N P A I]
time 15077ms: Process M started using the CPU for 103ms burst [Q H O F G E N P A I]
time 15107ms: Process B completed I/O; added to ready queue [Q H O F G E N P A I B]
time 15180ms: Process M completed a CPU burst; 35 bursts to go [Q H O F G E N P A I B]
time 15180ms: Process M switching out of CPU; will block on I/O until time 15196ms [Q H O F G E N P A I B]
time 15184ms: Process H started using the CPU for 29ms burst [Q O F G E N P A I B]
time 15196ms: Process M completed I/O; added to ready queue [Q O F G E N P A I B M]
time 15213ms: Process H completed a CPU burst; 70 bursts to go [Q O F G E N P A I B M]
time 15213ms: Process H switching out of CPU; will block on I/O until time 15437ms [Q O F G E N P A I B M]
time 15217ms: Process O started using the CPU for 45ms burst [Q F G E N P A I B M]
time 15262ms: Process O completed a CPU burst; 19 bursts to go [Q F G E N P A I B M]
time 15262ms: Process O switching out of CPU; will block on I/O until time 15310ms [Q F G E N P A I B M]
time 15266ms: Process F started using the CPU for 97ms burst [Q G E N P A I B M]
time 15310ms: Process O completed I/O; added to ready queue [Q G E N P A I B M O]
time 15363ms: Process F completed a CPU burst; 21 bursts to go [Q G E N P A I B M O]
time 15363ms: Process F switching out of CPU; will block on I/O until time 15369ms [Q G E N P A I B M O]
time 15367ms: Process G started using the CPU for 61ms burst [Q E N P A I B M O]
time 15369ms: Process F completed I/O; added to ready queue [Q E N P A I B M O F]
time 15428ms: Process G completed a CPU burst; 67 bursts to go [Q E N P A I B M O F]
time 15428ms: Process G switching out of CPU; will block on I/O until time 15504ms [Q E N P A I B M O F]
time 15432ms: Process E started using the CPU for 126ms burst [Q N P A I B M O F]
time 15437ms: Process H completed I/O; added to ready queue [Q N P A I B M O F H]
time 15504ms: Process G completed I/O; added to ready queue [Q N P A I B M O F H G]
time 15558ms: Process E completed a CPU burst; 42 bursts to go [Q N P A I B M O F H G]
time 15558ms: Process E switching out of CPU; will block on I/O until time 15758ms [Q N P A I B M O F H G]
time 15562ms: Process N started using the CPU for 39ms burst [Q P A I B M O F H G]
time 15601ms: Process N completed a CPU burst; 18 bursts to go [Q P A I B M O F H G]
time 15601ms: Process N switching out of CPU; will block on I/O until time 15604ms [Q P A I B M O F H G]
time 15604ms: Process N completed I/O; added to ready queue [Q A I B M O F H G N]
time 15605ms: Process P started using the CPU for 83ms burst [Q A I B M O F H G N]
time 15688ms: Process P completed a CPU burst; 4 bursts to go [Q A I B M O F H G N]
time 15688ms: Process P switching out of CPU; will block on I/O until time 15717ms [Q A I B M O F H G N]
time 15692ms: Process A started using the CPU for 62ms burst [Q I B M O F H G N]
time 15717ms: Process P completed I/O; added to ready queue [Q I B M O F H G N P]
time 15754ms: Process A completed a CPU burst; 2 bursts to go [Q I B M O F H G N P]
time 15754ms: Process A switching out of CPU; will block on I/O until time 15833ms [Q I B M O F H G N P]
time 15758ms: Process I started using the CPU for 65ms burst [Q B M O F H G N P]
time 15758ms: Process E completed I/O; added to ready queue [Q B M O F H G N P E]
time 15823ms: Process I completed a CPU burst; 64 bursts to go [Q B M O F H G N P E]
time 15823ms: Process I switching out of CPU; will block on I/O until time 15857ms [Q B M O F H G N P E]
time 15827ms: Process B started using the CPU for 144ms burst [Q M O F H G N P E]
time 15833ms: Process A completed I/O; added to ready queue [Q M O F H G N P E A]
time 15857ms: Process I completed I/O; added to ready queue [Q M O F H G N P E A I]
time 15971ms: Process B completed a CPU burst; 7 bursts to go [Q M O F H G N P E A I]
time 15971ms: Process B switching out of CPU; will block on I/O until time 16052ms [Q M O F H G N P E A I]
time 15975ms: Process M started using the CPU for 15ms burst [Q O F H G N P E A I]
time 15990ms: Process M completed a CPU burst; 34 bursts to go [Q O F H G N P E A I]
time 15990ms: Process M switching out of CPU; will block on I/O until time 16103ms [Q O F H G N P E A I]
time 15994ms: Process O started using the CPU for 50ms burst [Q F H G N P E A I]
time 16044ms: Process O completed a CPU burst; 18 bursts to go [Q F H G N P E A I]
time 16044ms: Process O switching out of CPU; will block on I/O until time 16157ms [Q F H G N P E A I]
time 16048ms: Process F started using the CPU for 157ms burst [Q H G N P E A I]
time 16052ms: Process B completed I/O; added to ready queue [Q H G N P E A I B]
time 16103ms: Process M completed I/O; added to ready queue [Q H G N P E A I B M]
time 16157ms: Process O completed I/O; added to ready queue [Q H G N P E A I B M O]
time 16205ms: Process F completed a CPU burst; 20 bursts to go [Q H G N P E A I B M O]
time 16205ms: Process F switching out of CPU; will block on I/O until time 16217ms [Q H G N P E A I B M O]
time 16209ms: Process H started using the CPU for 76ms burst [Q G N P E A I B M O]
time 16217ms: Process F completed I/O; added to ready queue [Q G N P E A I B M O F]
time 16285ms: Process H completed a CPU burst; 69 bursts to go [Q G N P E A I B M O F]
time 16285ms: Process H switching out of CPU; will block on I/O until time 16499ms [Q G N P E A I B M O F]
time 16289ms: Process G started using the CPU for 7ms burst [Q N P E A I B M O F]
time 16296ms: Process G completed a CPU burst; 66 bursts to go [Q N P E A I B M O F]
time 16296ms: Process G switching out of CPU; will block on I/O until time 16462ms [Q N P E A I B M O F]
time 16300ms: Process N started using the CPU for 137ms burst [Q P E A I B M O F]
time 16437ms: Process N completed a CPU burst; 17 bursts to go [Q P E A I B M O F]
time 16437ms: Process N switching out of CPU; will block on I/O until time 16458ms [Q P E A I B M O F]
time 16441ms: Process P started using the CPU for 75ms burst [Q E A I B M O F]
time 16458ms: Process N completed I/O; added to ready queue [Q E A I B M O F N]
time 16462ms: Process G completed I/O; added to ready queue [Q E A I B M O F N G]
time 16499ms: Process H completed I/O; added to ready queue [Q E A I B M O F N G H]
time 16516ms: Process P completed a CPU burst; 3 bursts to go [Q E A I B M O F N G H]
time 16516ms: Process P switching out of CPU; will block on I/O until time 16536ms [Q E A I B M O F N G H]
time 16520ms: Process E started using the CPU for 168ms burst [Q A I B M O F N G H]
time 16536ms: Process P completed I/O; added to ready queue [Q A I B M O F N G H P]
time 16688ms: Process E completed a CPU burst; 41 bursts to go [Q A I B M O F N G H P]
time 16688ms: Process E switching out of CPU; will block on I/O until time 16740ms [Q A I B M O F N G H P]
time 16692ms: Process A started using the CPU for 200ms burst [Q I B M O F N G H P]
time 16740ms: Process E completed I/O; added to ready queue [Q I B M O F N G H P E]
time 16892ms: Process A completed a CPU burst; 1 burst to go [Q I B M O F N G H P E]
time 16892ms: Process A switching out of CPU; will block on I/O until time 16905ms [Q I B M O F N G H P E]
time 16896ms: Process I started using the CPU for 58ms burst [Q B M O F N G H P E]
time 16905ms: Process A completed I/O; added to ready queue [Q B M O F N G H P E A]
time 16954ms: Process I completed a CPU burst; 63 bursts to go [Q B M O F N G H P E A]
time 16954ms: Process I switching out of CPU; will block on I/O until time 17130ms [Q B M O F N G H P E A]
time 16958ms: Process B started using the CPU for 183ms burst [Q M O F N G H P E A]
time 17130ms: Process I completed I/O; added to ready queue [Q M O F N G H P E A I]
time 17141ms: Process B completed a CPU burst; 6 bursts to go [Q M O F N G H P E A I]
time 17141ms: Process B switching out of CPU; will block on I/O until time 17149ms [Q M O F N G H P E A I]
time 17145ms: Process M started using the CPU for 26ms burst [Q O F N G H P E A I]
time 17149ms: Process B completed I/O; added to ready queue [Q O F N G H P E A I B]
time 17171ms: Process M completed a CPU burst; 33 bursts to go [Q O F N G H P E A I B]
time 17171ms: Process M switching out of CPU; will block on I/O until time 17233ms [Q O F N G H P E A I B]
time 17175ms: Process O started using the CPU for 133ms burst [Q F N G H P E A I B]
time 17233ms: Process M completed I/O; added to ready queue [Q F N G H P E A I B M]
time 17308ms: Process O completed a CPU burst; 17 bursts to go [Q F N G H P E A I B M]
time 17308ms: Process O switching out of CPU; will block on I/O until time 17438ms [Q F N G H P E A I B M]
time 17312ms: Process F started using the CPU for 24ms burst [Q N G H P E A I B M]
time 17336ms: Process F completed a CPU burst; 19 bursts to go [Q N G H P E A I B M]
time 17336ms: Process F switching out of CPU; will block on I/O until time 17435ms [Q N G H P E A I B M]
time 17340ms: Process N started using the CPU for 189ms burst [Q G H P E A I B M]
time 17435ms: Process F completed I/O; added to ready queue [Q G H P E A I B M F]
time 17438ms: Process O completed I/O; added to ready queue [Q G H P E A I B M F O]
time 17529ms: Process N completed a CPU burst; 16 bursts to go [Q G H P E A I B M F O]
time 17529ms: Process N switching out of CPU; will block on I/O until time 17694ms [Q G H P E A I B M F O]
time 17533ms: Process G started using the CPU for 2ms burst [Q H P E A I B M F O]
time 17535ms: Process G completed a CPU burst; 65 bursts to go [Q H P E A I B M F O]
time 17535ms: Process G switching out of CPU; will block on I/O until time 17548ms [Q H P E A I B M F O]
time 17539ms: Process H started using the CPU for 143ms burst [Q P E A I B M F O]
time 17548ms: Process G completed I/O; added to ready queue [Q P E A I B M F O G]
time 17682ms: Process H completed a CPU burst; 68 bursts to go [Q P E A I B M F O G]
time 17682ms: Process H switching out of CPU; will block on I/O until time 17868ms [Q P E A I B M F O G]
time 17686ms: Process P started using the CPU for 1ms burst [Q E A I B M F O G]
time 17687ms: Process P completed a CPU burst; 2 bursts to go [Q E A I B M F O G]
time 17687ms: Process P switching out of CPU; will block on I/O until time 17707ms [Q E A I B M F O G]
time 17691ms: Process E started using the CPU for 23ms burst [Q A I B M F O G]
time 17694ms: Process N completed I/O; added to ready queue [Q A I B M F O G N]
time 17707ms: Process P completed I/O; added to ready queue [Q A I B M F O G N P]
time 17714ms: Process E completed a CPU burst; 40 bursts to go [Q A I B M F O G N P]
time 17714ms: Process E switching out of CPU; will block on I/O until time 17725ms [Q A I B M F O G N P]
time 17718ms: Process A started using the CPU for 197ms burst [Q I B M F O G N P]
time 17725ms: Process E completed I/O; added to ready queue [Q I B M F O G N P E]
time 17868ms: Process H completed I/O; added to ready queue [Q I B M F O G N P E H]
time 17915ms: Process A terminated [Q I B M F O G N P E H]
time 17919ms: Process I started using the CPU for 95ms burst [Q B M F O G N P E H]
time 18014ms: Process I completed a CPU burst; 62 bursts to go [Q B M F O G N P E H]
time 18014ms: Process I switching out of CPU; will block on I/O until time 18158ms [Q B M F O G N P E H]
time 18018ms: Process B started using the CPU for 219ms burst [Q M F O G N P E H]
time 18158ms: Process I completed I/O; added to ready queue [Q M F O G N P E H I]
time 18237ms: Process B completed a CPU burst; 5 bursts to go [Q M F O G N P E H I]
time 18237ms: Process B switching out of CPU; will block on I/O until time 18262ms [Q M F O G N P E H I]
time 18241ms: Process M started using the CPU for 74ms burst [Q F O G N P E H I]
time 18262ms: Process B completed I/O; added to ready queue [Q F O G N P E H I B]
time 18315ms: Process M completed a CPU burst; 32 bursts to go [Q F O G N P E H I B]
time 18315ms: Process M switching out of CPU; will block on I/O until time 18438ms [Q F O G N P E H I B]
time 18319ms: Process F started using the CPU for 31ms burst [Q O G N P E H I B]
time 18350ms: Process F completed a CPU burst; 18 bursts to go [Q O G N P E H I B]
time 18350ms: Process F switching out of CPU; will block on I/O until time 18373ms [Q O G N P E H I B]
time 18354ms: Process O started using the CPU for 74ms burst [Q G N P E H I B]
time 18373ms: Process F completed I/O; added to ready queue [Q G N P E H I B F]
time 18428ms: Process O completed a CPU burst; 16 bursts to go [Q G N P E H I B F]
time 18428ms: Process O switching out of CPU; will block on I/O until time 18519ms [Q G N P E H I B F]
time 18432ms: Process G started using the CPU for 209ms burst [Q N P E H I B F]
time 18438ms: Process M completed I/O; added to ready queue [Q N P E H I B F M]
time 18519ms: Process O completed I/O; added to ready queue [Q N P E H I B F M O]
time 18641ms: Process G completed a CPU burst; 64 bursts to go [Q N P E H I B F M O]
time 18641ms: Process G switching out of CPU; will block on I/O until time 18691ms [Q N P E H I B F M O]
time 18645ms: Process N started using the CPU for 67ms burst [Q P E H I B F M O]
time 18691ms: Process G completed I/O; added to ready queue [Q P E H I B F M O G]
time 18712ms: Process N completed a CPU burst; 15 bursts to go [Q P E H I B F M O G]
time 18712ms: Process N switching out of CPU; will block on I/O until time 18756ms [Q P E H I B F M O G]
time 18716ms: Process P started using the CPU for 131ms burst [Q E H I B F M O G]
time 18756ms: Process N completed I/O; added to ready queue [Q E H I B F M O G N]
time 18847ms: Process P completed a CPU burst; 1 burst to go [Q E H I B F M O G N]
time 18847ms: Process P switching out of CPU; will block on I/O until time 18894ms [Q E H I B F M O G N]
time 18851ms: Process E started using the CPU for 68ms burst [Q H I B F M O G N]
time 18894ms: Process P completed I/O; added to ready queue [Q H I B F M O G N P]
time 18919ms: Process E completed a CPU burst; 39 bursts to go [Q H I B F M O G N P]
time 18919ms: Process E switching out of CPU; will block on I/O until time 18979ms [Q H I B F M O G N P]
time 18923ms: Process H started using the CPU for 32ms burst [Q I B F M O G N P]
time 18955ms: Process H completed a CPU burst; 67 bursts to go [Q I B F M O G N P]
time 18955ms: Process H switching out of CPU; will block on I/O until time 19039ms [Q I B F M O G N P]
time 18959ms: Process I started using the CPU for 78ms burst [Q B F M O G N P]
time 18979ms: Process E completed I/O; added to ready queue [Q B F M O G N P E]
time 19037ms: Process I completed a CPU burst; 61 bursts to go [Q B F M O G N P E]
time 19037ms: Process I switching out of CPU; will block on I/O until time 19116ms [Q B F M O G N P E]
time 19039ms: Process H completed I/O; added to ready queue [Q B F M O G N P E H]
time 19041ms: Process B started using the CPU for 64ms burst [Q F M O G N P E H]
time 19105ms: Process B completed a CPU burst; 4 bursts to go [Q F M O G N P E H]
time 19105ms: Process B switching out of CPU; will block on I/O until time 19187ms [Q F M O G N P E H]
time 19109ms: Process F started using the CPU for 24ms burst [Q M O G N P E H]
time 19116ms: Process I completed I/O; added to ready queue [Q M O G N P E H I]
time 19133ms: Process F completed a CPU burst; 17 bursts to go [Q M O G N P E H I]
time 19133ms: Process F switching out of CPU; will block on I/O until time 19194ms [Q M O G N P E H I]
time 19137ms: Process M started using the CPU for 6ms burst [Q O G N P E H I]
time 19143ms: Process M completed a CPU burst; 31 bursts to go [Q O G N P E H I]
time 19143ms: Process M switching out of CPU; will block on I/O until time 19249ms [Q O G N P E H I]
time 19147ms: Process O started using the CPU for 41ms burst [Q G N P E H I]
time 19187ms: Process B completed I/O; added to ready queue [Q G N P E H I B]
time 19188ms: Process O completed a CPU burst; 15 bursts to go [Q G N P E H I B]
time 19188ms: Process O switching out of CPU; will block on I/O until time 19247ms [Q G N P E H I B]
time 19192ms: Process G started using the CPU for 6ms burst [Q N P E H I B]
time 19194ms: Process F completed I/O; added to ready queue [Q N P E H I B F]
time 19198ms: Process G completed a CPU burst; 63 bursts to go [Q N P E H I B F]
time 19198ms: Process G switching out of CPU; will block on I/O until time 19348ms [Q N P E H I B F]
time 19202ms: Process N started using the CPU for 35ms burst [Q P E H I B F]
time 19237ms: Process N completed a CPU burst; 14 bursts to go [Q P E H I B F]
time 19237ms: Process N switching out of CPU; will block on I/O until time 19343ms [Q P E H I B F]
time 19241ms: Process P started using the CPU for 9ms burst [Q E H I B F]
time 19247ms: Process O completed I/O; added to ready queue [Q E H I B F O]
time 19249ms: Process M completed I/O; added to ready queue [Q E H I B F O M]
time 19250ms: Process P terminated [Q E H I B F O M]
time 19254ms: Process E started using the CPU for 41ms burst [Q H I B F O M]
time 19295ms: Process E completed a CPU burst; 38 bursts to go [Q H I B F O M]
time 19295ms: Process E switching out of CPU; will block on I/O until time 19317ms [Q H I B F O M]
time 19299ms: Process H started using the CPU for 78ms burst [Q I B F O M]
time 19317ms: Process E completed I/O; added to ready queue [Q I B F O M E]
time 19343ms: Process N completed I/O; added to ready queue [Q I B F O M E N]
time 19348ms: Process G completed I/O; added to ready queue [Q I B F O M E N G]
time 19377ms: Process H completed a CPU burst; 66 bursts to go [Q I B F O M E N G]
time 19377ms: Process H switching out of CPU; will block on I/O until time 19385ms [Q I B F O M E N G]
time 19381ms: Process I started using the CPU for 31ms burst [Q B F O M E N G]
time 19385ms: Process H completed I/O; added to ready queue [Q B F O M E N G H]
time 19412ms: Process I completed a CPU burst; 60 bursts to go [Q B F O M E N G H]
time 19412ms: Process I switching out of CPU; will block on I/O until time 19523ms [Q B F O M E N G H]
time 19416ms: Process B started using the CPU for 33ms burst [Q F O M E N G H]
time 19449ms: Process B completed a CPU burst; 3 bursts to go [Q F O M E N G H]
time 19449ms: Process B switching out of CPU; will block on I/O until time 19525ms [Q F O M E N G H]
time 19453ms: Process F started using the CPU for 135ms burst [Q O M E N G H]
time 19523ms: Process I completed I/O; added to ready queue [Q O M E N G H I]
time 19525ms: Process B completed I/O; added to ready queue [Q O M E N G H I B]
time 19588ms: Process F completed a CPU burst; 16 bursts to go [Q O M E N G H I B]
time 19588ms: Process F switching out of CPU; will block on I/O until time 19652ms [Q O M E N G H I B]
time 19592ms: Process O started using the CPU for 57ms burst [Q M E N G H I B]
time 19649ms: Process O completed a CPU burst; 14 bursts to go [Q M E N G H I B]
time 19649ms: Process O switching out of CPU; will block on I/O until time 19679ms [Q M E N G H I B]
time 19652ms: Process F completed I/O; added to ready queue [Q E N G H I B F]
time 19653ms: Process M started using the CPU for 216ms burst [Q E N G H I B F]
time 19679ms: Process O completed I/O; added to ready queue [Q E N G H I B F O]
time 19869ms: Process M completed a CPU burst; 30 bursts to go [Q E N G H I B F O]
time 19869ms: Process M switching out of CPU; will block on I/O until time 19991ms [Q E N G H I B F O]
time 19873ms: Process E started using the CPU for 44ms burst [Q N G H I B F O]
time 19917ms: Process E completed a CPU burst; 37 bursts to go [Q N G H I B F O]
time 19917ms: Process E switching out of CPU; will block on I/O until time 19980ms [Q N G H I B F O]
time 19921ms: Process N started using the CPU for 2ms burst [Q G H I B F O]
time 19923ms: Process N completed a CPU burst; 13 bursts to go [Q G H I B F O]
time 19923ms: Process N switching out of CPU; will block on I/O until time 20055ms [Q G H I B F O]
time 19927ms: Process G started using the CPU for 37ms burst [Q H I B F O]
time 19964ms: Process G completed a CPU burst; 62 bursts to go [Q H I B F O]
time 19964ms: Process G switching out of CPU; will block on I/O until time 20097ms [Q H I B F O]
time 19968ms: Process H started using the CPU for 16ms burst [Q I B F O]
time 19980ms: Process E completed I/O; added to ready queue [Q I B F O E]
time 19984ms: Process H completed a CPU burst; 65 bursts to go [Q I B F O E]
time 19984ms: Process H switching out of CPU; will block on I/O until time 20041ms [Q I B F O E]
time 19988ms: Process I started using the CPU for 97ms burst [Q B F O E]
time 19991ms: Process M completed I/O; added to ready queue [Q B F O E M]
time 20041ms: Process H completed I/O; added to ready queue [Q B F O E M H]
time 20055ms: Process N completed I/O; added to ready queue [Q B F O E M H N]
time 20085ms: Process I completed a CPU burst; 59 bursts to go [Q B F O E M H N]
time 20085ms: Process I switching out of CPU; will block on I/O until time 20105ms [Q B F O E M H N]
time 20089ms: Process B started using the CPU for 63ms burst [Q F O E M H N]
time 20097ms: Process G completed I/O; added to ready queue [Q F O E M H N G]
time 20105ms: Process I completed I/O; added to ready queue [Q F O E M H N G I]
time 20152ms: Process B completed a CPU burst; 2 bursts to go [Q F O E M H N G I]
time 20152ms: Process B switching out of CPU; will block on I/O until time 20385ms [Q F O E M H N G I]
time 20156ms: Process F started using the CPU for 87ms burst [Q O E M H N G I]
time 20243ms: Process F completed a CPU burst; 15 bursts to go [Q O E M H N G I]
time 20243ms: Process F switching out of CPU; will block on I/O until time 20349ms [Q O E M H N G I]
time 20247ms: Process O started using the CPU for 159ms burst [Q E M H N G I]
time 20349ms: Process F completed I/O; added to ready queue [Q E M H N G I F]
time 20385ms: Process B completed I/O; added to ready queue [Q E M H N G I F B]
time 20406ms: Process O completed a CPU burst; 13 bursts to go [Q E M H N G I F B]
time 20406ms: Process O switching out of CPU; will block on I/O until time 20509ms [Q E M H N G I F B]
time 20410ms: Process E started using the CPU for 74ms burst [Q M H N G I F B]
time 20484ms: Process E completed a CPU burst; 36 bursts to go [Q M H N G I F B]
time 20484ms: Process E switching out of CPU; will block on I/O until time 20672ms [Q M H N G I F B]
time 20488ms: Process M started using the CPU for 3ms burst [Q H N G I F B]
time 20491ms: Process M completed a CPU burst; 29 bursts to go [Q H N G I F B]
time 20491ms: Process M switching out of CPU; will block on I/O until time 20518ms [Q H N G I F B]
time 20495ms: Process H started using the CPU for 142ms burst [Q N G I F B]
time 20509ms: Process O completed I/O; added to ready queue [Q N G I F B O]
time 20518ms: Process M completed I/O; added to ready queue [Q N G I F B O M]
time 20637ms: Process H completed a CPU burst; 64 bursts to go [Q N G I F B O M]
time 20637ms: Process H switching out of CPU; will block on I/O until time 20736ms [Q N G I F B O M]
time 20641ms: Process N started using the CPU for 158ms burst [Q G I F B O M]
time 20672ms: Process E completed I/O; added to ready queue [Q G I F B O M E]
time 20736ms: Process H completed I/O; added to ready queue [Q G I F B O M E H]
time 20799ms: Process N completed a CPU burst; 12 bursts to go [Q G I F B O M E H]
time 20799ms: Process N switching out of CPU; will block on I/O until time 20992ms [Q G I F B O M E H]
time 20803ms: Process G started using the CPU for 15ms burst [Q I F B O M E H]
time 20818ms: Process G completed a CPU burst; 61 bursts to go [Q I F B O M E H]
time 20818ms: Process G switching out of CPU; will block on I/O until time 20842ms [Q I F B O M E H]
time 20822ms: Process I started using the CPU for 103ms burst [Q F B O M E H]
time 20842ms: Process G completed I/O; added to ready queue [Q F B O M E H G]
time 20925ms: Process I completed a CPU burst; 58 bursts to go [Q F B O M E H G]
time 20925ms: Process I switching out of CPU; will block on I/O until time 21014ms [Q F B O M E H G]
time 20929ms: Process F started using the CPU for 22ms burst [Q B O M E H G]
time 20951ms: Process F completed a CPU burst; 14 bursts to go [Q B O M E H G]
time 20951ms: Process F switching out of CPU; will block on I/O until time 20968ms [Q B O M E H G]
time 20955ms: Process B started using the CPU for 170ms burst [Q O M E H G]
time 20968ms: Process F completed I/O; added to ready queue [Q O M E H G F]
time 20992ms: Process N completed I/O; added to ready queue [Q O M E H G F N]
time 21014ms: Process I completed I/O; added to ready queue [Q O M E H G F N I]
time 21125ms: Process B completed a CPU burst; 1 burst to go [Q O M E H G F N I]
time 21125ms: Process B switching out of CPU; will block on I/O until time 21184ms [Q O M E H G F N I]
time 21129ms: Process O started using the CPU for 87ms burst [Q M E H G F N I]
time 21184ms: Process B completed I/O; added to ready queue [Q M E H G F N I B]
time 21216ms: Process O completed a CPU burst; 12 bursts to go [Q M E H G F N I B]
time 21216ms: Process O switching out of CPU; will block on I/O until time 21379ms [Q M E H G F N I B]
time 21220ms: Process M started using the CPU for 67ms burst [Q E H G F N I B]
time 21287ms: Process M completed a CPU burst; 28 bursts to go [Q E H G F N I B]
time 21287ms: Process M switching out of CPU; will block on I/O until time 21318ms [Q E H G F N I B]
time 21291ms: Process E started using the CPU for 117ms burst [Q H G F N I B]
time 21318ms: Process M completed I/O; added to ready queue [Q H G F N I B M]
time 21379ms: Process O completed I/O; added to ready queue [Q H G F N I B M O]
time 21408ms: Process E completed a CPU burst; 35 bursts to go [Q H G F N I B M O]
time 21408ms: Process E switching out of CPU; will block on I/O until time 21510ms [Q H G F N I B M O]
time 21412ms: Process H started using the CPU for 62ms burst [Q G F N I B M O]
time 21474ms: Process H completed a CPU burst; 63 bursts to go [Q G F N I B M O]
time 21474ms: Process H switching out of CPU; will block on I/O until time 21501ms [Q G F N I B M O]
time 21478ms: Process G started using the CPU for 47ms burst [Q F N I B M O]
time 21501ms: Process H completed I/O; added to ready queue [Q F N I B M O H]
time 21510ms: Process E completed I/O; added to ready queue [Q F N I B M O H E]
time 21525ms: Process G completed a CPU burst; 60 bursts to go [Q F N I B M O H E]
time 21525ms: Process G switching out of CPU; will block on I/O until time 21603ms [Q F N I B M O H E]
time 21529ms: Process F started using the CPU for 52ms burst [Q N I B M O H E]
time 21581ms: Process F completed a CPU burst; 13 bursts to go [Q N I B M O H E]
time 21581ms: Process F switching out of CPU; will block on I/O until time 21592ms [Q N I B M O H E]
time 21585ms: Process N started using the CPU for 52ms burst [Q I B M O H E]
time 21592ms: Process F completed I/O; added to ready queue [Q I B M O H E F]
time 21603ms: Process G completed I/O; added to ready queue [Q I B M O H E F G]
time 21637ms: Process N completed a CPU burst; 11 bursts to go [Q I B M O H E F G]
time 21637ms: Process N switching out of CPU; will block on I/O until time 21641ms [Q I B M O H E F G]
time 21641ms: Process I started using the CPU for 44ms burst [Q B M O H E F G]
time 21641ms: Process N completed I/O; added to ready queue [Q B M O H E F G N]
time 21685ms: Process I completed a CPU burst; 57 bursts to go [Q B M O H E F G N]
time 21685ms: Process I switching out of CPU; will block on I/O until time 21886ms [Q B M O H E F G N]
time 21689ms: Process B started using the CPU for 212ms burst [Q M O H E F G N]
time 21886ms: Process I completed I/O; added to ready queue [Q M O H E F G N I]
time 21901ms: Process B terminated [Q M O H E F G N I]
time 21905ms: Process M started using the CPU for 217ms burst [Q O H E F G N I]
time 22122ms: Process M completed a CPU burst; 27 bursts to go [Q O H E F G N I]
time 22122ms: Process M switching out of CPU; will block on I/O until time 22168ms [Q O H E F G N I]
time 22126ms: Process O started using the CPU for 127ms burst [Q H E F G N I]
time 22168ms: Process M completed I/O; added to ready queue [Q H E F G N I M]
time 22253ms: Process O completed a CPU burst; 11 bursts to go [Q H E F G N I M]
time 22253ms: Process O switching out of CPU; will block on I/O until time 22471ms [Q H E F G N I M]
time 22257ms: Process H started using the CPU for 248ms burst [Q E F G N I M]
time 22471ms: Process O completed I/O; added to ready queue [Q E F G N I M O]
time 22505ms: Process H completed a CPU burst; 62 bursts to go [Q E F G N I M O]
time 22505ms: Process H switching out of CPU; will block on I/O until time 22589ms [Q E F G N I M O]
time 22509ms: Process E started using the CPU for 14ms burst [Q F G N I M O]
time 22523ms: Process E completed a CPU burst; 34 bursts to go [Q F G N I M O]
time 22523ms: Process E switching out of CPU; will block on I/O until time 22527ms [Q F G N I M O]
time 22527ms: Process F started using the CPU for 90ms burst [Q G N I M O]
time 22527ms: Process E completed I/O; added to ready queue [Q G N I M O E]
time 22589ms: Process H completed I/O; added to ready queue [Q G N I M O E H]
time 22617ms: Process F completed a CPU burst; 12 bursts to go [Q G N I M O E H]
time 22617ms: Process F switching out of CPU; will block on I/O until time 22840ms [Q G N I M O E H]
time 22621ms: Process G started using the CPU for 82ms burst [Q N I M O E H]
time 22703ms: Process G completed a CPU burst; 59 bursts to go [Q N I M O E H]
time 22703ms: Process G switching out of CPU; will block on I/O until time 22708ms [Q N I M O E H]
time 22707ms: Process N started using the CPU for 251ms burst [Q I M O E H]
time 22708ms: Process G completed I/O; added to ready queue [Q I M O E H G]
time 22840ms: Process F completed I/O; added to ready queue [Q I M O E H G F]
time 22958ms: Process N completed a CPU burst; 10 bursts to go [Q I M O E H G F]
time 22958ms: Process N switching out of CPU; will block on I/O until time 23200ms [Q I M O E H G F]
time 22962ms: Process I started using the CPU for 37ms burst [Q M O E H G F]
time 22999ms: Process I completed a CPU burst; 56 bursts to go [Q M O E H G F]
time 22999ms: Process I switching out of CPU; will block on I/O until time 23091ms [Q M O E H G F]
time 23003ms: Process M started using the CPU for 19ms burst [Q O E H G F]
time 23022ms: Process M completed a CPU burst; 26 bursts to go [Q O E H G F]
time 23022ms: Process M switching out of CPU; will block on I/O until time 23164ms [Q O E H G F]
time 23026ms: Process O started using the CPU for 9ms burst [Q E H G F]
time 23035ms: Process O completed a CPU burst; 10 bursts to go [Q E H G F]
time 23035ms: Process O switching out of CPU; will block on I/O until time 23044ms [Q E H G F]
time 23039ms: Process E started using the CPU for 156ms burst [Q H G F]
time 23044ms: Process O completed I/O; added to ready queue [Q H G F O]
time 23091ms: Process I completed I/O; added to ready queue [Q H G F O I]
time 23164ms: Process M completed I/O; added to ready queue [Q H G F O I M]
time 23195ms: Process E completed a CPU burst; 33 bursts to go [Q H G F O I M]
time 23195ms: Process E switching out of CPU; will block on I/O until time 23297ms [Q H G F O I M]
time 23199ms: Process H started using the CPU for 37ms burst [Q G F O I M]
time 23200ms: Process N completed I/O; added to ready queue [Q G F O I M N]
time 23236ms: Process H completed a CPU burst; 61 bursts to go [Q G F O I M N]
time 23236ms: Process H switching out of CPU; will block on I/O until time 23241ms [Q G F O I M N]
time 23240ms: Process G started using the CPU for 57ms burst [Q F O I M N]
time 23241ms: Process H completed I/O; added to ready queue [Q F O I M N H]
time 23297ms: Process G completed a CPU burst; 58 bursts to go [Q F O I M N H]
time 23297ms: Process G switching out of CPU; will block on I/O until time 23320ms [Q F O I M N H]
time 23297ms: Process E completed I/O; added to ready queue [Q F O I M N H E]
time 23301ms: Process F started using the CPU for 4ms burst [Q O I M N H E]
time 23305ms: Process F completed a CPU burst; 11 bursts to go [Q O I M N H E]
time 23305ms: Process F switching out of CPU; will block on I/O until time 23362ms [Q O I M N H E]
time 23309ms: Process O started using the CPU for 54ms burst [Q I M N H E]
